File: stat-thermo/polymers/lab_cure_data.csv
,Time (s),Load (N),Tensile strain (Extension) (mm/mm),Tensile extension (mm),Tensile stress (MPa),sample
0,0.00000,6.71945,0.00000,0.00000,0.28861,1-1
1,0.10000,10.97002,0.00094,0.01312,0.47117,1-1
2,0.20000,10.87472,0.00236,0.03287,0.46708,1-1
3,0.30000,11.61723,0.00359,0.04994,0.49897,1-1
4,0.40000,11.51747,0.00479,0.06656,0.49469,1-1
5,0.50000,11.61764,0.00599,0.08331,0.49899,1-1
6,0.60000,11.71586,0.00719,0.10006,0.50321,1-1
7,0.70000,11.94172,0.00838,0.11662,0.51291,1-1
8,0.80000,11.93436,0.00959,0.13337,0.51259,1-1
9,0.90000,12.35936,0.01078,0.14994,0.53085,1-1
10,1.00000,12.19877,0.01198,0.16662,0.52395,1-1
11,1.10000,13.30476,0.01318,0.18331,0.57145,1-1
12,1.20000,13.13836,0.01437,0.19987,0.56430,1-1
13,1.30000,13.22762,0.01558,0.21675,0.56814,1-1
14,1.40000,13.58710,0.01677,0.23325,0.58358,1-1
15,1.50000,14.13250,0.01797,0.24994,0.60700,1-1
16,1.60000,14.51390,0.01918,0.26675,0.62338,1-1
17,1.70000,16.61559,0.02037,0.28331,0.71365,1-1
18,1.80000,25.29967,0.02157,0.30006,1.08664,1-1
19,1.90000,49.41716,0.02276,0.31662,2.12251,1-1
20,2.00000,78.84286,0.02396,0.33325,3.38637,1-1
21,2.10000,110.01405,0.02517,0.35006,4.72520,1-1
22,2.20000,141.79646,0.02636,0.36662,6.09029,1-1
23,2.30000,172.48909,0.02756,0.38337,7.40856,1-1
24,2.40000,203.37282,0.02875,0.39994,8.73505,1-1
25,2.50000,234.70163,0.02995,0.41662,10.08065,1-1
26,2.60000,266.11166,0.03115,0.43331,11.42974,1-1
27,2.70000,296.98199,0.03235,0.45000,12.75564,1-1
28,2.80000,326.98007,0.03355,0.46662,14.04409,1-1
29,2.90000,357.24783,0.03474,0.48325,15.34412,1-1
30,3.00000,386.66971,0.03595,0.50006,16.60781,1-1
31,3.10000,416.56363,0.03715,0.51669,17.89178,1-1
32,3.20000,445.77502,0.03834,0.53331,19.14644,1-1
33,3.30000,474.43152,0.03954,0.55006,20.37726,1-1
34,3.40000,502.69977,0.04074,0.56662,21.59141,1-1
35,3.50000,530.97430,0.04194,0.58337,22.80582,1-1
36,3.60000,559.10431,0.04314,0.60006,24.01403,1-1
37,3.70000,586.14642,0.04433,0.61662,25.17552,1-1
38,3.80000,612.83716,0.04553,0.63337,26.32191,1-1
39,3.90000,639.97656,0.04672,0.64994,27.48757,1-1
40,4.00000,666.22498,0.04792,0.66662,28.61496,1-1
41,4.10000,692.00226,0.04913,0.68337,29.72212,1-1
42,4.20000,717.61383,0.05032,0.69994,30.82216,1-1
43,4.30000,742.35742,0.05152,0.71669,31.88492,1-1
44,4.40000,767.69061,0.05271,0.73325,32.97300,1-1
45,4.50000,791.92706,0.05392,0.75006,34.01398,1-1
46,4.60000,815.85413,0.05512,0.76669,35.04167,1-1
47,4.70000,839.12891,0.05631,0.78331,36.04134,1-1
48,4.80000,862.11420,0.05752,0.80012,37.02858,1-1
49,4.90000,884.62073,0.05871,0.81662,37.99525,1-1
50,5.00000,906.50806,0.05991,0.83331,38.93534,1-1
51,5.10000,928.18121,0.06111,0.85006,39.86622,1-1
52,5.20000,949.08215,0.06230,0.86662,40.76393,1-1
53,5.30000,969.45337,0.06351,0.88337,41.63889,1-1
54,5.40000,990.04175,0.06470,0.90000,42.52318,1-1
55,5.50000,1009.63275,0.06590,0.91662,43.36464,1-1
56,5.60000,1028.59741,0.06710,0.93337,44.17918,1-1
57,5.70000,1047.01733,0.06829,0.94994,44.97034,1-1
58,5.80000,1065.02576,0.06950,0.96669,45.74381,1-1
59,5.90000,1082.17676,0.07069,0.98325,46.48046,1-1
60,6.00000,1098.51709,0.07189,1.00000,47.18230,1-1
61,6.10000,1115.00281,0.07309,1.01669,47.89037,1-1
62,6.20000,1130.62146,0.07429,1.03331,48.56121,1-1
63,6.30000,1145.42761,0.07549,1.05000,49.19714,1-1
64,6.40000,1160.17224,0.07668,1.06662,49.83044,1-1
65,6.50000,1173.56299,0.07788,1.08331,50.40559,1-1
66,6.60000,1187.25500,0.07908,1.10006,50.99367,1-1
67,6.70000,1199.25659,0.08027,1.11662,51.50915,1-1
68,6.80000,1210.76343,0.08148,1.13344,52.00338,1-1
69,6.90000,1222.15100,0.08267,1.14994,52.49249,1-1
70,7.00000,1232.20740,0.08387,1.16662,52.92442,1-1
71,7.10000,1242.25012,0.08507,1.18337,53.35576,1-1
72,7.20000,1251.20032,0.08627,1.20000,53.74018,1-1
73,7.30000,1259.78223,0.08747,1.21675,54.10878,1-1
74,7.40000,1267.56201,0.08866,1.23325,54.44293,1-1
75,7.50000,1274.74036,0.08986,1.25000,54.75124,1-1
76,7.60000,1281.05151,0.09106,1.26669,55.02231,1-1
77,7.70000,1287.73706,0.09226,1.28337,55.30946,1-1
78,7.80000,1292.18274,0.09346,1.30006,55.50041,1-1
79,7.84200,762.34106,0.09398,1.30725,32.74323,1-1
80,0.00000,2.58535,0.00083,0.01281,0.12785,1-2
81,0.10000,38.58710,0.00211,0.03231,1.90821,1-2
82,0.20000,62.63884,0.00323,0.04956,3.09762,1-2
83,0.30000,65.71213,0.00431,0.06619,3.24960,1-2
84,0.40000,68.72739,0.00540,0.08294,3.39871,1-2
85,0.50000,70.58333,0.00649,0.09969,3.49049,1-2
86,0.60000,70.97856,0.00757,0.11625,3.51004,1-2
87,0.70000,72.32620,0.00866,0.13300,3.57668,1-2
88,0.80000,72.68523,0.00975,0.14962,3.59444,1-2
89,0.90000,73.78452,0.01083,0.16625,3.64880,1-2
90,1.00000,74.24947,0.01191,0.18287,3.67179,1-2
91,1.10000,74.16354,0.01300,0.19956,3.66754,1-2
92,1.20000,75.90797,0.01410,0.21644,3.75381,1-2
93,1.30000,82.19318,0.01518,0.23294,4.06462,1-2
94,1.40000,93.66981,0.01626,0.24962,4.63217,1-2
95,1.50000,107.99877,0.01735,0.26637,5.34076,1-2
96,1.60000,126.39725,0.01843,0.28287,6.25061,1-2
97,1.70000,149.40906,0.01952,0.29969,7.38859,1-2
98,1.80000,174.59520,0.02061,0.31631,8.63409,1-2
99,1.90000,198.61581,0.02169,0.33287,9.82196,1-2
100,2.00000,222.87723,0.02279,0.34975,11.02174,1-2
101,2.10000,247.16267,0.02386,0.36631,12.22271,1-2
102,2.20000,270.80417,0.02496,0.38306,13.39183,1-2
103,2.30000,293.94824,0.02604,0.39969,14.53635,1-2
104,2.40000,317.15628,0.02712,0.41631,15.68404,1-2
105,2.50000,340.45950,0.02821,0.43300,16.83643,1-2
106,2.60000,363.11755,0.02930,0.44969,17.95691,1-2
107,2.70000,385.60880,0.03038,0.46631,19.06915,1-2
108,2.80000,408.01031,0.03146,0.48294,20.17696,1-2
109,2.90000,430.49194,0.03255,0.49969,21.28872,1-2
110,3.00000,452.22440,0.03364,0.51631,22.36343,1-2
111,3.10000,473.80551,0.03472,0.53294,23.43066,1-2
112,3.20000,495.01578,0.03581,0.54975,24.47956,1-2
113,3.30000,516.39478,0.03689,0.56631,25.53679,1-2
114,3.40000,537.31104,0.03798,0.58300,26.57114,1-2
115,3.50000,558.20435,0.03907,0.59969,27.60436,1-2
116,3.60000,578.28009,0.04014,0.61619,28.59715,1-2
117,3.70000,598.41736,0.04124,0.63306,29.59298,1-2
118,3.80000,618.93536,0.04232,0.64969,30.60764,1-2
119,3.90000,638.95953,0.04341,0.66631,31.59787,1-2
120,4.00000,659.44537,0.04450,0.68300,32.61094,1-2
121,4.10000,678.89612,0.04557,0.69956,33.57282,1-2
122,4.20000,697.82104,0.04667,0.71637,34.50870,1-2
123,4.30000,716.62988,0.04775,0.73294,35.43883,1-2
124,4.40000,735.47040,0.04884,0.74969,36.37054,1-2
125,4.50000,753.71405,0.04993,0.76637,37.27272,1-2
126,4.60000,771.98206,0.05101,0.78294,38.17611,1-2
127,4.70000,789.58997,0.05210,0.79975,39.04686,1-2
128,4.80000,806.86298,0.05318,0.81631,39.90105,1-2
129,4.90000,823.44220,0.05427,0.83300,40.72092,1-2
130,5.00000,839.82867,0.05536,0.84975,41.53127,1-2
131,5.10000,856.08167,0.05644,0.86631,42.33501,1-2
132,5.20000,871.35107,0.05753,0.88306,43.09011,1-2
133,5.30000,886.84827,0.05861,0.89962,43.85648,1-2
134,5.40000,900.61584,0.05969,0.91631,44.53732,1-2
135,5.50000,914.79376,0.06079,0.93306,45.23845,1-2
136,5.60000,928.19873,0.06186,0.94962,45.90135,1-2
137,5.70000,941.05194,0.06296,0.96637,46.53697,1-2
138,5.80000,953.37567,0.06403,0.98287,47.14640,1-2
139,5.90000,965.93469,0.06512,0.99962,47.76747,1-2
140,6.00000,977.18872,0.06621,1.01637,48.32401,1-2
141,6.10000,988.41840,0.06730,1.03300,48.87934,1-2
142,6.20000,998.37982,0.06839,1.04975,49.37195,1-2
143,6.30000,1007.92218,0.06947,1.06631,49.84384,1-2
144,6.40000,1016.51990,0.07055,1.08300,50.26902,1-2
145,6.50000,1024.51855,0.07164,1.09975,50.66457,1-2
146,6.60000,1031.08337,0.07272,1.11631,50.98921,1-2
147,6.70000,1037.16174,0.07382,1.13306,51.28980,1-2
148,6.80000,1042.17395,0.07489,1.14962,51.53766,1-2
149,6.90000,1046.08740,0.07598,1.16631,51.73119,1-2
150,7.00000,1048.85535,0.07707,1.18300,51.86807,1-2
151,7.10000,1049.69824,0.07816,1.19969,51.90975,1-2
152,7.20000,1049.34363,0.07925,1.21644,51.89222,1-2
153,7.30000,1044.63159,0.08032,1.23294,51.65919,1-2
154,7.32800,573.05524,0.08065,1.23794,28.33877,1-2
155,0.00000,8.57049,0.00000,0.00000,0.35151,1-3
156,0.10000,10.12796,0.00089,0.01325,0.41539,1-3
157,0.20000,11.01041,0.00220,0.03281,0.45158,1-3
158,0.30000,10.62616,0.00335,0.04994,0.43582,1-3
159,0.40000,11.57421,0.00446,0.06650,0.47470,1-3
160,0.50000,12.03725,0.00559,0.08331,0.49369,1-3
161,0.60000,13.07314,0.00671,0.10000,0.53618,1-3
162,0.70000,13.47377,0.00782,0.11656,0.55261,1-3
163,0.80000,14.22968,0.00895,0.13337,0.58361,1-3
164,0.90000,15.25411,0.01006,0.14994,0.62563,1-3
165,1.00000,18.32618,0.01117,0.16656,0.75163,1-3
166,1.10000,28.30096,0.01229,0.18325,1.16073,1-3
167,1.20000,51.44446,0.01341,0.19994,2.10994,1-3
168,1.30000,79.65645,0.01454,0.21675,3.26702,1-3
169,1.40000,110.15392,0.01564,0.23319,4.51784,1-3
170,1.50000,140.16614,0.01676,0.24994,5.74875,1-3
171,1.60000,170.17044,0.01789,0.26669,6.97935,1-3
172,1.70000,200.02397,0.01900,0.28325,8.20376,1-3
173,1.80000,230.16986,0.02012,0.30006,9.44016,1-3
174,1.90000,260.27106,0.02124,0.31662,10.67472,1-3
175,2.00000,289.62646,0.02235,0.33325,11.87870,1-3
176,2.10000,319.70361,0.02348,0.35006,13.11228,1-3
177,2.20000,348.74341,0.02459,0.36662,14.30331,1-3
178,2.30000,377.73328,0.02571,0.38337,15.49230,1-3
179,2.40000,407.08356,0.02683,0.40000,16.69607,1-3
180,2.50000,436.14209,0.02794,0.41662,17.88787,1-3
181,2.60000,464.93695,0.02906,0.43331,19.06886,1-3
182,2.70000,493.58578,0.03018,0.44994,20.24386,1-3
183,2.80000,521.75287,0.03130,0.46669,21.39910,1-3
184,2.90000,550.68512,0.03241,0.48325,22.58572,1-3
185,3.00000,578.26526,0.03354,0.50006,23.71689,1-3
186,3.10000,606.07343,0.03465,0.51669,24.85741,1-3
187,3.20000,633.62817,0.03577,0.53337,25.98754,1-3
188,3.30000,660.92029,0.03690,0.55012,27.10689,1-3
189,3.40000,687.93488,0.03800,0.56656,28.21487,1-3
190,3.50000,713.57990,0.03913,0.58337,29.26667,1-3
191,3.60000,739.97241,0.04025,0.60006,30.34913,1-3
192,3.70000,765.17902,0.04135,0.61656,31.38295,1-3
193,3.80000,790.23346,0.04248,0.63337,32.41053,1-3
194,3.90000,815.03961,0.04359,0.65000,33.42792,1-3
195,4.00000,838.76233,0.04471,0.66662,34.40088,1-3
196,4.10000,862.44385,0.04583,0.68331,35.37215,1-3
197,4.20000,886.09308,0.04694,0.69994,36.34210,1-3
198,4.30000,908.71277,0.04807,0.71669,37.26982,1-3
199,4.40000,931.16797,0.04918,0.73331,38.19080,1-3
200,4.50000,952.71094,0.05030,0.75000,39.07436,1-3
201,4.60000,974.09131,0.05142,0.76669,39.95125,1-3
202,4.70000,994.77332,0.05254,0.78331,40.79950,1-3
203,4.80000,1015.41376,0.05366,0.80012,41.64604,1-3
204,4.90000,1034.94995,0.05477,0.81662,42.44730,1-3
205,5.00000,1054.22522,0.05589,0.83331,43.23785,1-3
206,5.10000,1072.97668,0.05702,0.85012,44.00692,1-3
207,5.20000,1090.88354,0.05812,0.86662,44.74135,1-3
208,5.30000,1107.89685,0.05925,0.88337,45.43913,1-3
209,5.40000,1124.67126,0.06036,0.90000,46.12711,1-3
210,5.50000,1140.53479,0.06148,0.91662,46.77774,1-3
211,5.60000,1156.34399,0.06260,0.93337,47.42613,1-3
212,5.70000,1171.27148,0.06371,0.94994,48.03837,1-3
213,5.80000,1185.03845,0.06483,0.96662,48.60300,1-3
214,5.90000,1198.53186,0.06594,0.98319,49.15642,1-3
215,6.00000,1211.24768,0.06707,1.00000,49.67795,1-3
216,6.10000,1223.23303,0.06819,1.01675,50.16951,1-3
217,6.20000,1234.61658,0.06930,1.03331,50.63639,1-3
218,6.30000,1245.06604,0.07043,1.05006,51.06497,1-3
219,6.40000,1254.75586,0.07154,1.06662,51.46238,1-3
220,6.50000,1263.93335,0.07266,1.08337,51.83879,1-3
221,6.60000,1272.38464,0.07378,1.10006,52.18541,1-3
222,6.70000,1279.96326,0.07490,1.11669,52.49624,1-3
223,6.80000,1286.51135,0.07601,1.13337,52.76480,1-3
224,6.90000,1292.37732,0.07713,1.15000,53.00539,1-3
225,7.00000,1297.70483,0.07825,1.16669,53.22389,1-3
226,7.10000,1302.01501,0.07936,1.18331,53.40067,1-3
227,7.20000,1305.57703,0.08048,1.20000,53.54676,1-3
228,7.30000,1307.99414,0.08161,1.21675,53.64589,1-3
229,7.40000,1310.01099,0.08272,1.23331,53.72861,1-3
230,7.50000,1311.35876,0.08383,1.24994,53.78389,1-3
231,7.60000,1311.78809,0.08496,1.26669,53.80149,1-3
232,7.62600,751.15961,0.08526,1.27125,30.80796,1-3
233,0.00000,2.27574,0.00078,0.01081,0.11095,2-1
234,0.10000,13.84561,0.00222,0.03069,0.67505,2-1
235,0.20000,19.20872,0.00346,0.04781,0.93653,2-1
236,0.30000,19.01129,0.00467,0.06456,0.92691,2-1
237,0.40000,17.37236,0.00587,0.08125,0.84700,2-1
238,0.50000,16.80661,0.00709,0.09806,0.81941,2-1
239,0.60000,17.16574,0.00828,0.11456,0.83692,2-1
240,0.70000,18.78492,0.00949,0.13131,0.91587,2-1
241,0.80000,21.61832,0.01070,0.14794,1.05401,2-1
242,0.90000,25.24148,0.01189,0.16444,1.23066,2-1
243,1.00000,31.07099,0.01311,0.18131,1.51488,2-1
244,1.10000,39.14534,0.01431,0.19787,1.90855,2-1
245,1.20000,47.87699,0.01552,0.21469,2.33427,2-1
246,1.30000,58.02077,0.01672,0.23125,2.82883,2-1
247,1.40000,70.49592,0.01792,0.24787,3.43706,2-1
248,1.50000,84.29449,0.01914,0.26475,4.10982,2-1
249,1.60000,99.17095,0.02034,0.28125,4.83513,2-1
250,1.70000,112.97109,0.02155,0.29800,5.50796,2-1
251,1.80000,127.25688,0.02275,0.31469,6.20447,2-1
252,1.90000,140.80482,0.02395,0.33119,6.86501,2-1
253,2.00000,156.58424,0.02517,0.34812,7.63435,2-1
254,2.10000,174.36316,0.02636,0.36462,8.50117,2-1
255,2.20000,192.05594,0.02757,0.38131,9.36379,2-1
256,2.30000,210.04266,0.02878,0.39800,10.24074,2-1
257,2.40000,227.70103,0.02998,0.41462,11.10168,2-1
258,2.50000,245.19980,0.03119,0.43131,11.95484,2-1
259,2.60000,262.51486,0.03239,0.44794,12.79905,2-1
260,2.70000,278.94803,0.03360,0.46469,13.60026,2-1
261,2.80000,296.11276,0.03480,0.48131,14.43713,2-1
262,2.90000,312.14490,0.03601,0.49800,15.21879,2-1
263,3.00000,328.57898,0.03722,0.51475,16.02004,2-1
264,3.10000,344.61072,0.03842,0.53131,16.80167,2-1
265,3.20000,360.41449,0.03962,0.54800,17.57220,2-1
266,3.30000,376.06592,0.04083,0.56469,18.33529,2-1
267,3.40000,391.77914,0.04203,0.58131,19.10139,2-1
268,3.50000,406.85449,0.04325,0.59812,19.83640,2-1
269,3.60000,422.33508,0.04444,0.61456,20.59117,2-1
270,3.70000,436.49319,0.04564,0.63119,21.28145,2-1
271,3.80000,451.67740,0.04685,0.64794,22.02176,2-1
272,3.90000,466.03946,0.04805,0.66456,22.72199,2-1
273,4.00000,480.55634,0.04927,0.68137,23.42977,2-1
274,4.10000,494.83328,0.05047,0.69794,24.12585,2-1
275,4.20000,508.48898,0.05168,0.71475,24.79164,2-1
276,4.30000,522.34906,0.05288,0.73131,25.46740,2-1
277,4.40000,535.57214,0.05409,0.74800,26.11210,2-1
278,4.50000,548.87592,0.05530,0.76475,26.76073,2-1
279,4.60000,561.55963,0.05649,0.78131,27.37913,2-1
280,4.70000,573.53491,0.05771,0.79812,27.96299,2-1
281,4.80000,585.26343,0.05891,0.81469,28.53482,2-1
282,4.90000,596.59027,0.06011,0.83131,29.08707,2-1
283,5.00000,608.04529,0.06133,0.84812,29.64556,2-1
284,5.10000,618.69196,0.06252,0.86462,30.16465,2-1
285,5.20000,629.10132,0.06372,0.88131,30.67216,2-1
286,5.30000,639.95898,0.06494,0.89806,31.20153,2-1
287,5.40000,649.13849,0.06612,0.91450,31.64908,2-1
288,5.50000,658.74860,0.06734,0.93137,32.11763,2-1
289,5.60000,667.73083,0.06853,0.94781,32.55556,2-1
290,5.70000,676.70264,0.06975,0.96462,32.99298,2-1
291,5.80000,685.09723,0.07096,0.98131,33.40227,2-1
292,5.90000,692.30139,0.07216,0.99800,33.75351,2-1
293,6.00000,699.71094,0.07338,1.01481,34.11477,2-1
294,6.10000,706.46844,0.07457,1.03131,34.44423,2-1
295,6.20000,712.55096,0.07578,1.04806,34.74079,2-1
296,6.30000,718.63324,0.07699,1.06475,35.03733,2-1
297,6.40000,723.52319,0.07818,1.08125,35.27575,2-1
298,6.50000,728.06122,0.07940,1.09812,35.49700,2-1
299,6.60000,732.12872,0.08059,1.11462,35.69531,2-1
300,6.70000,735.45569,0.08180,1.13131,35.85752,2-1
301,6.80000,738.16663,0.08301,1.14800,35.98969,2-1
302,6.90000,740.33600,0.08421,1.16462,36.09546,2-1
303,7.00000,741.65363,0.08542,1.18131,36.15971,2-1
304,7.10000,742.72968,0.08662,1.19800,36.21217,2-1
305,7.20000,742.62036,0.08783,1.21469,36.20684,2-1
306,7.30000,742.35797,0.08903,1.23131,36.19405,2-1
307,7.40000,740.83850,0.09023,1.24794,36.11996,2-1
308,7.50000,739.29095,0.09145,1.26475,36.04451,2-1
309,7.60000,737.10461,0.09265,1.28131,35.93792,2-1
310,7.70000,733.89050,0.09385,1.29800,35.78121,2-1
311,7.80000,730.37091,0.09506,1.31462,35.60961,2-1
312,7.90000,726.41888,0.09626,1.33131,35.41693,2-1
313,8.00000,722.47375,0.09748,1.34812,35.22458,2-1
314,8.10000,717.50409,0.09868,1.36469,34.98228,2-1
315,8.20000,712.06677,0.09988,1.38137,34.71718,2-1
316,8.30000,707.28326,0.10108,1.39800,34.48396,2-1
317,8.40000,701.10059,0.10229,1.41462,34.18252,2-1
318,8.50000,695.41449,0.10350,1.43144,33.90529,2-1
319,8.60000,689.12305,0.10470,1.44800,33.59855,2-1
320,8.70000,682.85486,0.10591,1.46469,33.29294,2-1
321,8.80000,675.90997,0.10711,1.48131,32.95434,2-1
322,8.90000,668.99774,0.10832,1.49800,32.61733,2-1
323,9.00000,661.78845,0.10952,1.51469,32.26584,2-1
324,9.10000,654.38947,0.11072,1.53131,31.90510,2-1
325,9.20000,646.47174,0.11193,1.54800,31.51906,2-1
326,9.30000,637.60883,0.11314,1.56469,31.08695,2-1
327,9.40000,627.21289,0.11433,1.58125,30.58009,2-1
328,9.50000,615.64270,0.11555,1.59806,30.01598,2-1
329,9.60000,601.85809,0.11675,1.61462,29.34390,2-1
330,9.70000,586.41064,0.11796,1.63144,28.59075,2-1
331,9.80000,568.97260,0.11917,1.64806,27.74055,2-1
332,9.90000,550.15143,0.12036,1.66462,26.82292,2-1
333,10.00000,529.29291,0.12157,1.68137,25.80595,2-1
334,10.10000,506.53735,0.12278,1.69800,24.69649,2-1
335,10.20000,481.64697,0.12398,1.71469,23.48295,2-1
336,10.30000,454.80444,0.12519,1.73137,22.17422,2-1
337,10.33000,445.23090,0.12555,1.73631,21.70746,2-1
338,0.00000,1.23478,0.01077,0.15700,0.06086,2-2
339,0.10000,3.97782,0.01188,0.17319,0.19607,2-2
340,0.20000,5.21745,0.01303,0.18994,0.25717,2-2
341,0.30000,6.82478,0.01417,0.20662,0.33640,2-2
342,0.40000,8.00624,0.01531,0.22325,0.39463,2-2
343,0.50000,9.56056,0.01646,0.24000,0.47124,2-2
344,0.60000,10.61652,0.01760,0.25662,0.52329,2-2
345,0.70000,12.08379,0.01875,0.27331,0.59561,2-2
346,0.80000,14.37130,0.01989,0.29000,0.70836,2-2
347,0.90000,16.02885,0.02103,0.30662,0.79007,2-2
348,1.00000,17.46382,0.02218,0.32337,0.86080,2-2
349,1.10000,18.31048,0.02332,0.33994,0.90253,2-2
350,1.20000,20.27620,0.02446,0.35662,0.99942,2-2
351,1.30000,22.39075,0.02561,0.37344,1.10365,2-2
352,1.40000,24.54295,0.02674,0.38994,1.20973,2-2
353,1.50000,27.59338,0.02790,0.40675,1.36008,2-2
354,1.60000,35.29821,0.02903,0.42331,1.73986,2-2
355,1.70000,45.89857,0.03018,0.44000,2.26235,2-2
356,1.80000,58.50735,0.03132,0.45669,2.88384,2-2
357,1.90000,70.02323,0.03246,0.47325,3.45146,2-2
358,2.00000,79.61645,0.03362,0.49012,3.92431,2-2
359,2.10000,89.78108,0.03475,0.50662,4.42533,2-2
360,2.20000,100.79583,0.03590,0.52337,4.96825,2-2
361,2.30000,112.91258,0.03704,0.54000,5.56549,2-2
362,2.40000,126.86781,0.03818,0.55662,6.25334,2-2
363,2.50000,141.72574,0.03933,0.57344,6.98569,2-2
364,2.60000,157.73958,0.04047,0.59006,7.77502,2-2
365,2.70000,173.31107,0.04160,0.60656,8.54254,2-2
366,2.80000,188.68636,0.04275,0.62325,9.30039,2-2
367,2.90000,203.85086,0.04389,0.63987,10.04785,2-2
368,3.00000,218.97929,0.04504,0.65675,10.79354,2-2
369,3.10000,234.24937,0.04618,0.67325,11.54620,2-2
370,3.20000,249.08531,0.04732,0.68994,12.27747,2-2
371,3.30000,264.33710,0.04847,0.70669,13.02923,2-2
372,3.40000,278.49512,0.04961,0.72337,13.72709,2-2
373,3.50000,292.23404,0.05075,0.74000,14.40428,2-2
374,3.60000,306.44092,0.05190,0.75669,15.10454,2-2
375,3.70000,320.10944,0.05304,0.77331,15.77826,2-2
376,3.80000,334.09122,0.05419,0.79006,16.46743,2-2
377,3.90000,347.34680,0.05532,0.80662,17.12080,2-2
378,4.00000,360.37601,0.05648,0.82344,17.76301,2-2
379,4.10000,373.24042,0.05762,0.84006,18.39710,2-2
380,4.20000,386.25623,0.05875,0.85662,19.03865,2-2
381,4.30000,399.06982,0.05990,0.87331,19.67024,2-2
382,4.40000,411.44217,0.06104,0.89000,20.28008,2-2
383,4.50000,423.62259,0.06219,0.90669,20.88045,2-2
384,4.60000,435.96365,0.06333,0.92331,21.48874,2-2
385,4.70000,447.94055,0.06447,0.94000,22.07909,2-2
386,4.80000,459.07959,0.06561,0.95662,22.62813,2-2
387,4.90000,470.28894,0.06675,0.97325,23.18064,2-2
388,5.00000,481.46277,0.06790,0.99000,23.73141,2-2
389,5.10000,492.31580,0.06904,1.00656,24.26635,2-2
390,5.20000,503.29105,0.07019,1.02337,24.80733,2-2
391,5.30000,513.51007,0.07133,1.04000,25.31102,2-2
392,5.40000,523.47333,0.07247,1.05662,25.80212,2-2
393,5.50000,533.11255,0.07362,1.07337,26.27724,2-2
394,5.60000,542.88635,0.07476,1.09006,26.75899,2-2
395,5.70000,552.10834,0.07590,1.10669,27.21354,2-2
396,5.80000,560.80579,0.07705,1.12337,27.64224,2-2
397,5.90000,569.13629,0.07818,1.13994,28.05285,2-2
398,6.00000,577.16357,0.07934,1.15681,28.44852,2-2
399,6.10000,585.07819,0.08047,1.17325,28.83863,2-2
400,6.20000,592.88330,0.08162,1.19000,29.22335,2-2
401,6.30000,600.16779,0.08276,1.20669,29.58240,2-2
402,6.40000,606.62396,0.08390,1.22325,29.90063,2-2
403,6.50000,613.41974,0.08505,1.24006,30.23559,2-2
404,6.60000,619.36835,0.08619,1.25662,30.52880,2-2
405,6.70000,625.35510,0.08733,1.27331,30.82389,2-2
406,6.80000,630.48944,0.08848,1.29000,31.07696,2-2
407,6.90000,635.64886,0.08962,1.30662,31.33127,2-2
408,7.00000,639.74078,0.09077,1.32337,31.53296,2-2
409,7.10000,644.03027,0.09191,1.34000,31.74439,2-2
410,7.20000,647.32397,0.09305,1.35669,31.90674,2-2
411,7.30000,650.39124,0.09420,1.37337,32.05793,2-2
412,7.40000,652.79340,0.09534,1.39000,32.17633,2-2
413,7.50000,654.98969,0.09648,1.40675,32.28459,2-2
414,7.60000,655.97076,0.09763,1.42337,32.33294,2-2
415,7.70000,656.61871,0.09877,1.44000,32.36488,2-2
416,7.80000,656.67645,0.09991,1.45675,32.36773,2-2
417,7.90000,656.57941,0.10105,1.47325,32.36295,2-2
418,8.00000,655.67474,0.10219,1.49000,32.31835,2-2
419,8.10000,654.51056,0.10334,1.50662,32.26097,2-2
420,8.20000,652.60706,0.10448,1.52331,32.16714,2-2
421,8.30000,650.05359,0.10562,1.54000,32.04129,2-2
422,8.40000,647.19000,0.10676,1.55662,31.90014,2-2
423,8.50000,643.99493,0.10791,1.57337,31.74265,2-2
424,8.60000,640.31482,0.10906,1.59006,31.56126,2-2
425,8.70000,635.99261,0.11019,1.60656,31.34822,2-2
426,8.80000,631.68817,0.11135,1.62344,31.13605,2-2
427,8.90000,627.20331,0.11248,1.64000,30.91499,2-2
428,9.00000,622.00769,0.11363,1.65675,30.65890,2-2
429,9.10000,616.72565,0.11477,1.67331,30.39854,2-2
430,9.20000,611.63928,0.11591,1.69000,30.14783,2-2
431,9.30000,606.26868,0.11705,1.70662,29.88312,2-2
432,9.40000,600.76581,0.11820,1.72331,29.61188,2-2
433,9.50000,595.40460,0.11934,1.74000,29.34762,2-2
434,9.60000,590.13177,0.12048,1.75656,29.08772,2-2
435,9.70000,584.44440,0.12163,1.77331,28.80739,2-2
436,9.80000,578.63330,0.12278,1.79006,28.52096,2-2
437,9.90000,572.90607,0.12391,1.80662,28.23867,2-2
438,10.00000,567.26227,0.12506,1.82344,27.96048,2-2
439,10.10000,561.32257,0.12620,1.84000,27.66771,2-2
440,10.20000,554.89575,0.12734,1.85662,27.35093,2-2
441,10.30000,548.03406,0.12849,1.87337,27.01272,2-2
442,10.40000,540.30328,0.12963,1.89000,26.63167,2-2
443,10.50000,531.12695,0.13078,1.90675,26.17937,2-2
444,10.60000,520.95581,0.13191,1.92331,25.67803,2-2
445,10.70000,508.63428,0.13306,1.94000,25.07070,2-2
446,10.80000,494.88855,0.13421,1.95675,24.39317,2-2
447,10.90000,476.68527,0.13534,1.97325,23.49592,2-2
448,11.00000,453.11154,0.13649,1.99000,22.33397,2-2
449,11.10000,417.51364,0.13762,2.00656,20.57934,2-2
450,11.14400,393.23285,0.13813,2.01400,19.38253,2-2
451,0.00000,8.32958,0.00000,-0.00006,0.40609,2-3
452,0.10000,10.70169,0.00095,0.01287,0.52173,2-3
453,0.20000,13.60105,0.00241,0.03275,0.66308,2-3
454,0.30000,17.58321,0.00367,0.04987,0.85722,2-3
455,0.40000,21.72488,0.00489,0.06650,1.05914,2-3
456,0.50000,25.60031,0.00613,0.08331,1.24807,2-3
457,0.60000,26.55580,0.00736,0.10000,1.29465,2-3
458,0.70000,29.11356,0.00858,0.11656,1.41935,2-3
459,0.80000,32.55809,0.00981,0.13331,1.58728,2-3
460,0.90000,37.66435,0.01103,0.14987,1.83622,2-3
461,1.00000,43.04636,0.01226,0.16656,2.09860,2-3
462,1.10000,59.00599,0.01348,0.18325,2.87667,2-3
463,1.20000,73.78098,0.01471,0.19987,3.59698,2-3
464,1.30000,85.42837,0.01595,0.21675,4.16482,2-3
465,1.40000,97.00752,0.01716,0.23325,4.72933,2-3
466,1.50000,109.26628,0.01839,0.24994,5.32697,2-3
467,1.60000,124.19558,0.01962,0.26669,6.05481,2-3
468,1.70000,140.38353,0.02084,0.28325,6.84400,2-3
469,1.80000,158.12502,0.02208,0.30000,7.70894,2-3
470,1.90000,175.97725,0.02330,0.31662,8.57928,2-3
471,2.00000,193.37538,0.02452,0.33319,9.42747,2-3
472,2.10000,210.06726,0.02576,0.35006,10.24124,2-3
473,2.20000,227.39865,0.02698,0.36669,11.08618,2-3
474,2.30000,244.05354,0.02821,0.38344,11.89814,2-3
475,2.40000,260.90637,0.02943,0.39994,12.71976,2-3
476,2.50000,277.37381,0.03066,0.41662,13.52258,2-3
477,2.60000,293.18689,0.03189,0.43337,14.29350,2-3
478,2.70000,309.03281,0.03311,0.45000,15.06603,2-3
479,2.80000,324.51096,0.03434,0.46669,15.82062,2-3
480,2.90000,339.78625,0.03556,0.48331,16.56532,2-3
481,3.00000,355.03217,0.03680,0.50012,17.30860,2-3
482,3.10000,370.17606,0.03802,0.51669,18.04689,2-3
483,3.20000,384.89496,0.03924,0.53331,18.76447,2-3
484,3.30000,399.53192,0.04048,0.55006,19.47806,2-3
485,3.40000,414.19757,0.04169,0.56656,20.19304,2-3
486,3.50000,427.81079,0.04293,0.58337,20.85671,2-3
487,3.60000,442.24765,0.04415,0.60006,21.56054,2-3
488,3.70000,455.56296,0.04536,0.61650,22.20969,2-3
489,3.80000,468.82663,0.04660,0.63331,22.85632,2-3
490,3.90000,481.96460,0.04783,0.65000,23.49683,2-3
491,4.00000,495.19489,0.04905,0.66662,24.14183,2-3
492,4.10000,507.95468,0.05028,0.68331,24.76390,2-3
493,4.20000,520.65002,0.05150,0.69994,25.38283,2-3
494,4.30000,533.28741,0.05274,0.71675,25.99893,2-3
495,4.40000,545.18732,0.05396,0.73325,26.57907,2-3
496,4.50000,557.27740,0.05519,0.75006,27.16849,2-3
497,4.60000,569.29218,0.05642,0.76675,27.75424,2-3
498,4.70000,580.66406,0.05764,0.78337,28.30864,2-3
499,4.80000,591.72095,0.05887,0.80006,28.84769,2-3
500,4.90000,602.35681,0.06009,0.81662,29.36621,2-3
501,5.00000,612.88647,0.06132,0.83337,29.87956,2-3
502,5.10000,623.25000,0.06255,0.85006,30.38480,2-3
503,5.20000,633.59497,0.06377,0.86662,30.88914,2-3
504,5.30000,643.69159,0.06500,0.88337,31.38137,2-3
505,5.40000,653.02771,0.06622,0.89994,31.83653,2-3
506,5.50000,662.19379,0.06745,0.91669,32.28340,2-3
507,5.60000,670.94037,0.06868,0.93337,32.70981,2-3
508,5.70000,679.40210,0.06990,0.94987,33.12234,2-3
509,5.80000,687.27148,0.07113,0.96669,33.50599,2-3
510,5.90000,695.01379,0.07235,0.98319,33.88344,2-3
511,6.00000,702.23578,0.07358,1.00000,34.23553,2-3
512,6.10000,709.49243,0.07482,1.01675,34.58931,2-3
513,6.20000,715.79559,0.07603,1.03331,34.89660,2-3
514,6.30000,722.08405,0.07727,1.05012,35.20318,2-3
515,6.40000,727.92078,0.07849,1.06662,35.48773,2-3
516,6.50000,733.06409,0.07972,1.08337,35.73848,2-3
517,6.60000,738.14905,0.08095,1.10006,35.98638,2-3
518,6.70000,742.76074,0.08217,1.11669,36.21121,2-3
519,6.80000,746.73389,0.08340,1.13337,36.40491,2-3
520,6.90000,750.28516,0.08462,1.15000,36.57804,2-3
521,7.00000,753.49493,0.08584,1.16662,36.73453,2-3
522,7.10000,755.61682,0.08707,1.18331,36.83797,2-3
523,7.20000,757.17194,0.08830,1.19994,36.91379,2-3
524,7.30000,757.60327,0.08953,1.21669,36.93482,2-3
525,7.40000,757.85138,0.09075,1.23325,36.94691,2-3
526,7.50000,757.07471,0.09198,1.25000,36.90905,2-3
527,7.60000,755.11414,0.09321,1.26675,36.81347,2-3
528,7.70000,752.37494,0.09444,1.28337,36.67992,2-3
529,7.80000,748.50806,0.09566,1.30006,36.49141,2-3
530,7.90000,743.40619,0.09688,1.31662,36.24268,2-3
531,8.00000,737.37201,0.09811,1.33337,35.94850,2-3
532,8.10000,729.57629,0.09934,1.35006,35.56844,2-3
533,8.20000,721.40369,0.10056,1.36662,35.17001,2-3
534,8.30000,711.78217,0.10180,1.38344,34.70094,2-3
535,8.40000,701.41095,0.10301,1.39994,34.19532,2-3
536,8.50000,690.11481,0.10424,1.41669,33.64461,2-3
537,8.60000,678.94556,0.10547,1.43337,33.10008,2-3
538,8.70000,667.39984,0.10670,1.45000,32.53720,2-3
539,8.80000,656.86719,0.10793,1.46675,32.02371,2-3
540,8.90000,645.98352,0.10914,1.48325,31.49311,2-3
541,9.00000,636.44421,0.11038,1.50006,31.02805,2-3
542,9.10000,627.14337,0.11160,1.51669,30.57461,2-3
543,9.20000,618.27130,0.11283,1.53331,30.14208,2-3
544,9.30000,609.90594,0.11406,1.55006,29.73425,2-3
545,9.40000,601.40784,0.11528,1.56662,29.31995,2-3
546,9.50000,592.72803,0.11651,1.58331,28.89679,2-3
547,9.60000,583.41895,0.11773,1.60000,28.44295,2-3
548,9.70000,572.65375,0.11897,1.61675,27.91812,2-3
549,9.80000,559.92853,0.12019,1.63344,27.29774,2-3
550,9.90000,544.67749,0.12141,1.65000,26.55422,2-3
551,10.00000,525.58484,0.12264,1.66669,25.62341,2-3
552,10.10000,502.16843,0.12387,1.68337,24.48181,2-3
553,10.20000,470.34348,0.12509,1.70000,22.93027,2-3
554,10.24000,454.22064,0.12558,1.70669,22.14425,2-3