File: stat-thermo/polymers/optimal_cure_data.csv
Time (s),Load (N),Tensile strain (Extension) (mm/mm),Tensile extension (mm),Tensile stress (MPa),Sample,Mix
0,1.31014,0.00036,0.00544,0.12413,5,2
0.1,16.75251,0.00178,0.02675,1.58725,5,2
0.2,29.02918,0.00292,0.04375,2.75043,5,2
0.3,40.94808,0.00403,0.0605,3.87972,5,2
0.4,52.70107,0.00516,0.07737,4.99328,5,2
0.5,63.96272,0.00627,0.094,6.06029,5,2
0.6,75.07722,0.00737,0.11062,7.11336,5,2
0.7,86.1706,0.00849,0.12737,8.16442,5,2
0.8,97.0571,0.0096,0.144,9.19589,5,2
0.9,108.11744,0.01071,0.16069,10.24383,5,2
1,118.6246,0.01181,0.17719,11.23935,5,2
1.1,129.08575,0.01293,0.19394,12.23052,5,2
1.2,139.60332,0.01405,0.21075,13.22703,5,2
1.3,150.08008,0.01515,0.22725,14.21967,5,2
1.4,159.90479,0.01625,0.24381,15.15053,5,2
1.5,170.45723,0.01738,0.26075,16.15035,5,2
1.6,180.44696,0.01849,0.27737,17.09685,5,2
1.7,190.28909,0.0196,0.29394,18.02936,5,2
1.8,199.80185,0.0207,0.3105,18.93067,5,2
1.9,209.29692,0.02182,0.32737,19.8303,5,2
2,218.64954,0.02294,0.34406,20.71643,5,2
2.1,207.80748,0.02404,0.36056,19.68918,5,2
2.2,218.57649,0.02516,0.37737,20.70951,5,2
2.3,228.75374,0.02627,0.39406,21.67378,5,2
2.4,237.86754,0.02738,0.41069,22.53728,5,2
2.5,247.18779,0.02848,0.42719,23.42035,5,2
2.6,256.17499,0.0296,0.44394,24.27187,5,2
2.7,265.16367,0.03072,0.46075,25.12352,5,2
2.8,273.59033,0.03182,0.47737,25.92192,5,2
2.9,282.28824,0.03293,0.494,26.74602,5,2
3,290.68036,0.03405,0.51075,27.54115,5,2
3.1,298.80615,0.03516,0.52744,28.31105,5,2
3.2,306.90448,0.03627,0.544,29.07834,5,2
3.3,314.62796,0.03737,0.5605,29.81012,5,2
3.4,322.59341,0.0385,0.57744,30.56483,5,2
3.5,330.06052,0.0396,0.59406,31.27231,5,2
3.6,337.34509,0.0407,0.61056,31.96251,5,2
3.7,344.58408,0.04183,0.62744,32.64838,5,2
3.8,351.68021,0.04294,0.64406,33.32072,5,2
3.9,358.63354,0.04404,0.66062,33.97953,5,2
4,365.30502,0.04515,0.67725,34.61163,5,2
4.1,371.8566,0.04626,0.69394,35.23238,5,2
4.2,378.20334,0.04738,0.71075,35.83371,5,2
4.3,384.24435,0.04849,0.72731,36.40608,5,2
4.4,389.99863,0.04959,0.74387,36.95128,5,2
4.5,395.91711,0.05072,0.76081,37.51204,5,2
4.6,401.35794,0.05183,0.77744,38.02755,5,2
4.7,406.42755,0.05293,0.79394,38.50788,5,2
4.8,411.51755,0.05404,0.81062,38.99014,5,2
4.9,416.45282,0.05516,0.82744,39.45774,5,2
5,421.04419,0.05627,0.84406,39.89276,5,2
5.1,425.45694,0.05737,0.86062,40.31086,5,2
5.2,429.26749,0.05849,0.87731,40.6719,5,2
5.3,433.28915,0.05961,0.89412,41.05294,5,2
5.4,436.569,0.06071,0.91069,41.36369,5,2
5.5,439.82159,0.06181,0.92719,41.67187,5,2
5.6,442.68323,0.06294,0.94406,41.943,5,2
5.7,445.21307,0.06405,0.96075,42.1827,5,2
5.8,447.48477,0.06515,0.97731,42.39793,5,2
5.9,449.29251,0.06626,0.99394,42.56921,5,2
6,451.12869,0.06738,1.01069,42.74319,5,2
6.1,452.42886,0.0685,1.02744,42.86637,5,2
6.2,453.24335,0.0696,1.04406,42.94354,5,2
6.3,453.853,0.0707,1.0605,43.0013,5,2
6.4,454.45691,0.07183,1.0775,43.05853,5,2
6.5,454.25977,0.07293,1.094,43.03984,5,2
6.6,453.5838,0.07403,1.1105,42.9758,5,2
6.7,452.95508,0.07516,1.12737,42.91623,5,2
6.8,452.06537,0.07627,1.144,42.83193,5,2
6.9,450.76349,0.07737,1.16062,42.70858,5,2
7,448.7262,0.07848,1.17719,42.51556,5,2
7.1,447.17249,0.07959,1.19387,42.36835,5,2
7.2,445.1824,0.08072,1.21081,42.17979,5,2
7.3,442.67773,0.08182,1.22737,41.94248,5,2
7.4,440.02979,0.08292,1.24387,41.69159,5,2
7.5,437.50363,0.08405,1.26081,41.45225,5,2
7.6,434.5567,0.08516,1.27737,41.17303,5,2
7.7,431.76096,0.08627,1.294,40.90815,5,2
7.8,428.85779,0.08737,1.31056,40.63308,5,2
7.9,426.04129,0.08849,1.32737,40.36622,5,2
8,422.87506,0.08961,1.34412,40.06623,5,2
8.1,420.07413,0.0907,1.36056,39.80085,5,2
8.2,417.03204,0.09182,1.37731,39.51262,5,2
8.3,414.32321,0.09294,1.39412,39.25597,5,2
8.4,411.5141,0.09404,1.41062,38.98981,5,2
8.5,408.92862,0.09515,1.42725,38.74485,5,2
8.6,406.3989,0.09627,1.44406,38.50516,5,2
8.7,404.10226,0.09738,1.46069,38.28756,5,2
8.8,401.75696,0.09849,1.47737,38.06535,5,2
8.9,399.58615,0.0996,1.494,37.85967,5,2
9,397.47968,0.10072,1.51075,37.66009,5,2
9.1,395.41925,0.10183,1.52744,37.46487,5,2
9.2,393.46878,0.10292,1.54387,37.28007,5,2
9.3,391.4646,0.10404,1.56056,37.09018,5,2
9.4,389.72052,0.10517,1.5775,36.92493,5,2
9.5,387.63202,0.10626,1.59394,36.72705,5,2
9.6,385.25262,0.10737,1.61056,36.50161,5,2
9.7,382.3306,0.10849,1.62737,36.22476,5,2
9.794,268.89777,0.10954,1.64312,25.47731,5,2
0,1.34974,0.00028,0.00425,0.07181,4,2
0.1,18.50522,0.00168,0.02562,0.98453,4,2
0.2,34.95821,0.0028,0.04269,1.85987,4,2
0.3,50.74291,0.0039,0.0595,2.69967,4,2
0.4,66.63838,0.00501,0.07637,3.54535,4,2
0.5,82.65359,0.0061,0.09306,4.3974,4,2
0.6,98.38969,0.00718,0.10956,5.23461,4,2
0.7,114.15395,0.00829,0.12637,6.07331,4,2
0.8,129.87564,0.00938,0.14306,6.90975,4,2
0.9,145.31787,0.01047,0.15962,7.73132,4,2
1,160.53781,0.01156,0.17625,8.54106,4,2
1.1,175.42206,0.01265,0.19294,9.33295,4,2
1.2,189.93968,0.01375,0.20975,10.10532,4,2
1.3,204.46959,0.01484,0.22631,10.87836,4,2
1.4,186.23769,0.01592,0.24281,9.90837,4,2
1.5,203.93037,0.01703,0.25975,10.84967,4,2
1.6,219.41203,0.01812,0.27637,11.67334,4,2
1.7,233.90152,0.01921,0.29294,12.44422,4,2
1.8,248.11865,0.0203,0.3095,13.20061,4,2
1.9,262.33075,0.0214,0.32637,13.95673,4,2
2,276.21841,0.0225,0.34306,14.6956,4,2
2.1,289.63959,0.02358,0.35962,15.40964,4,2
2.2,302.92825,0.02468,0.37637,16.11663,4,2
2.3,316.43503,0.02577,0.393,16.83523,4,2
2.4,329.09009,0.02686,0.40962,17.50852,4,2
2.5,341.91324,0.02795,0.42619,18.19074,4,2
2.6,354.52448,0.02905,0.44294,18.8617,4,2
2.7,366.91843,0.03015,0.45981,19.52109,4,2
2.8,379.20233,0.03124,0.47637,20.17463,4,2
2.9,391.18674,0.03232,0.49294,20.81223,4,2
3,403.19138,0.03343,0.50975,21.45091,4,2
3.1,414.77829,0.03452,0.52637,22.06737,4,2
3.2,426.24857,0.03561,0.54306,22.67762,4,2
3.3,437.47,0.03669,0.5595,23.27463,4,2
3.4,448.90204,0.0378,0.57644,23.88285,4,2
3.5,459.97961,0.03889,0.59306,24.47221,4,2
3.6,470.57861,0.03997,0.6095,25.0361,4,2
3.7,481.31888,0.04108,0.62644,25.60752,4,2
3.8,491.93311,0.04217,0.64306,26.17222,4,2
3.9,501.96075,0.04325,0.65962,26.70572,4,2
4,512.25323,0.04435,0.67631,27.25331,4,2
4.1,522.07214,0.04544,0.69294,27.77571,4,2
4.2,532.12787,0.04654,0.70975,28.3107,4,2
4.3,541.58215,0.04763,0.72631,28.81369,4,2
4.4,551.00775,0.04871,0.74287,29.31516,4,2
4.5,560.56787,0.04982,0.75981,29.82379,4,2
4.6,569.67676,0.05091,0.77637,30.3084,4,2
4.7,578.53497,0.052,0.79294,30.77969,4,2
4.8,587.31067,0.05309,0.80956,31.24658,4,2
4.9,596.06671,0.05419,0.82644,31.71242,4,2
5,604.39642,0.05528,0.84306,32.15559,4,2
5.1,612.59253,0.05637,0.85962,32.59164,4,2
5.2,620.88397,0.05746,0.87631,33.03277,4,2
5.3,628.89764,0.05857,0.89312,33.45912,4,2
5.4,636.57684,0.05965,0.90969,33.86768,4,2
5.5,643.92731,0.06073,0.92619,34.25874,4,2
5.6,651.33167,0.06184,0.94306,34.65268,4,2
5.7,658.37579,0.06293,0.95975,35.02744,4,2
5.8,665.38147,0.06402,0.97631,35.40017,4,2
5.9,672.03937,0.06511,0.99294,35.75438,4,2
6,678.84491,0.06621,1.00969,36.11646,4,2
6.1,685.1944,0.06731,1.02644,36.45427,4,2
6.2,691.22339,0.0684,1.04306,36.77503,4,2
6.3,697.06561,0.06948,1.0595,37.08585,4,2
6.4,702.73553,0.07059,1.0765,37.3875,4,2
6.5,708.32831,0.07168,1.09306,37.68506,4,2
6.6,713.09369,0.07275,1.1095,37.93859,4,2
6.7,718.31879,0.07386,1.12637,38.21658,4,2
6.8,723.33905,0.07495,1.143,38.48367,4,2
6.9,727.65613,0.07604,1.15962,38.71335,4,2
7,731.50934,0.07713,1.17625,38.91835,4,2
7.1,735.31012,0.07822,1.19287,39.12056,4,2
7.2,739.24677,0.07933,1.20981,39.33001,4,2
7.3,742.3985,0.08042,1.22637,39.49769,4,2
7.4,745.36469,0.0815,1.24287,39.65549,4,2
7.5,748.62726,0.08261,1.25981,39.82907,4,2
7.6,750.79327,0.0837,1.27637,39.94431,4,2
7.7,753.35822,0.08479,1.293,40.08078,4,2
7.8,755.13123,0.08587,1.30956,40.1751,4,2
7.9,756.82001,0.08697,1.32631,40.26495,4,2
8,758.43994,0.08807,1.34312,40.35114,4,2
8.1,759.12524,0.08915,1.35956,40.3876,4,2
8.2,759.71027,0.09025,1.37631,40.41872,4,2
8.3,760.30847,0.09135,1.39312,40.45055,4,2
8.4,760.07629,0.09243,1.40956,40.43819,4,2
8.5,760.02985,0.09352,1.42625,40.43572,4,2
8.6,759.29108,0.09463,1.44306,40.39642,4,2
8.7,758.54974,0.09572,1.45969,40.35698,4,2
8.8,757.40417,0.09682,1.47644,40.29603,4,2
8.9,755.63074,0.0979,1.493,40.20168,4,2
9,753.73254,0.099,1.50969,40.10069,4,2
9.1,751.68994,0.10009,1.52644,39.99202,4,2
9.2,749.00519,0.10118,1.54294,39.84918,4,2
9.3,746.66113,0.10227,1.55956,39.72447,4,2
9.4,743.59222,0.10338,1.5765,39.5612,4,2
9.5,740.51154,0.10446,1.593,39.39729,4,2
9.6,736.90924,0.10555,1.60956,39.20564,4,2
9.7,733.27948,0.10665,1.62637,39.01253,4,2
9.8,729.68341,0.10774,1.64306,38.82121,4,2
9.9,725.84497,0.10884,1.65975,38.61699,4,2
10,721.68201,0.10991,1.67619,38.39551,4,2
10.1,717.95007,0.11102,1.693,38.19696,4,2
10.2,713.91833,0.11212,1.70987,37.98246,4,2
10.3,709.5957,0.1132,1.72625,37.75249,4,2
10.4,705.54834,0.11429,1.74294,37.53716,4,2
10.5,701.94843,0.1154,1.75981,37.34563,4,2
10.6,697.83008,0.11648,1.77631,37.12652,4,2
10.7,693.62384,0.11758,1.79306,36.90274,4,2
10.8,689.96606,0.11866,1.8095,36.70813,4,2
10.9,686.2464,0.11976,1.82637,36.51024,4,2
11,682.81683,0.12086,1.84312,36.32777,4,2
11.1,679.04639,0.12193,1.8595,36.12717,4,2
11.2,675.54468,0.12305,1.8765,35.94088,4,2
11.3,672.46484,0.12414,1.89312,35.77702,4,2
11.4,669.10571,0.12522,1.90956,35.5983,4,2
11.5,666.29303,0.12632,1.92631,35.44866,4,2
11.6,663.15808,0.12741,1.943,35.28187,4,2
11.7,660.39636,0.12851,1.95975,35.13494,4,2
11.8,657.51093,0.1296,1.97637,34.98143,4,2
11.9,654.96027,0.13068,1.99281,34.84573,4,2
12,652.68469,0.13179,2.00975,34.72466,4,2
12.1,650.06348,0.13288,2.02644,34.58521,4,2
12.2,647.62433,0.13396,2.04287,34.45543,4,2
12.3,645.40723,0.13506,2.05962,34.33748,4,2
12.4,643.28082,0.13616,2.07644,34.22435,4,2
12.5,641.1521,0.13725,2.09306,34.1111,4,2
12.6,639.16113,0.13834,2.10962,34.00517,4,2
12.7,637.20178,0.13943,2.12637,33.90092,4,2
12.8,635.24817,0.14053,2.14306,33.79699,4,2
12.9,633.46283,0.14162,2.15969,33.702,4,2
13,631.57654,0.1427,2.17619,33.60165,4,2
13.1,629.94244,0.1438,2.193,33.51471,4,2
13.2,628.39423,0.14491,2.20981,33.43234,4,2
13.3,626.73383,0.14599,2.22631,33.344,4,2
13.4,624.87225,0.14708,2.24294,33.24496,4,2
13.5,623.50629,0.14817,2.25962,33.17229,4,2
13.6,621.74292,0.14927,2.27637,33.07847,4,2
13.7,619.96045,0.15036,2.29306,32.98364,4,2
13.8,618.05865,0.15144,2.30944,32.88246,4,2
13.9,616.46619,0.15255,2.32644,32.79773,4,2
14,614.50562,0.15365,2.34312,32.69342,4,2
14.1,612.14917,0.15472,2.3595,32.56806,4,2
14.2,609.66351,0.15584,2.3765,32.43581,4,2
14.3,606.02069,0.15692,2.39306,32.242,4,2
14.372,446.14157,0.15771,2.40506,23.73598,4,2
0,1.31014,0.00036,0.00544,0.12413,3,2
0.1,16.75251,0.00178,0.02675,1.58725,3,2
0.2,29.02918,0.00292,0.04375,2.75043,3,2
0.3,40.94808,0.00403,0.0605,3.87972,3,2
0.4,52.70107,0.00516,0.07737,4.99328,3,2
0.5,63.96272,0.00627,0.094,6.06029,3,2
0.6,75.07722,0.00737,0.11062,7.11336,3,2
0.7,86.1706,0.00849,0.12737,8.16442,3,2
0.8,97.0571,0.0096,0.144,9.19589,3,2
0.9,108.11744,0.01071,0.16069,10.24383,3,2
1,118.6246,0.01181,0.17719,11.23935,3,2
1.1,129.08575,0.01293,0.19394,12.23052,3,2
1.2,139.60332,0.01405,0.21075,13.22703,3,2
1.3,150.08008,0.01515,0.22725,14.21967,3,2
1.4,159.90479,0.01625,0.24381,15.15053,3,2
1.5,170.45723,0.01738,0.26075,16.15035,3,2
1.6,180.44696,0.01849,0.27737,17.09685,3,2
1.7,190.28909,0.0196,0.29394,18.02936,3,2
1.8,199.80185,0.0207,0.3105,18.93067,3,2
1.9,209.29692,0.02182,0.32737,19.8303,3,2
2,218.64954,0.02294,0.34406,20.71643,3,2
2.1,207.80748,0.02404,0.36056,19.68918,3,2
2.2,218.57649,0.02516,0.37737,20.70951,3,2
2.3,228.75374,0.02627,0.39406,21.67378,3,2
2.4,237.86754,0.02738,0.41069,22.53728,3,2
2.5,247.18779,0.02848,0.42719,23.42035,3,2
2.6,256.17499,0.0296,0.44394,24.27187,3,2
2.7,265.16367,0.03072,0.46075,25.12352,3,2
2.8,273.59033,0.03182,0.47737,25.92192,3,2
2.9,282.28824,0.03293,0.494,26.74602,3,2
3,290.68036,0.03405,0.51075,27.54115,3,2
3.1,298.80615,0.03516,0.52744,28.31105,3,2
3.2,306.90448,0.03627,0.544,29.07834,3,2
3.3,314.62796,0.03737,0.5605,29.81012,3,2
3.4,322.59341,0.0385,0.57744,30.56483,3,2
3.5,330.06052,0.0396,0.59406,31.27231,3,2
3.6,337.34509,0.0407,0.61056,31.96251,3,2
3.7,344.58408,0.04183,0.62744,32.64838,3,2
3.8,351.68021,0.04294,0.64406,33.32072,3,2
3.9,358.63354,0.04404,0.66062,33.97953,3,2
4,365.30502,0.04515,0.67725,34.61163,3,2
4.1,371.8566,0.04626,0.69394,35.23238,3,2
4.2,378.20334,0.04738,0.71075,35.83371,3,2
4.3,384.24435,0.04849,0.72731,36.40608,3,2
4.4,389.99863,0.04959,0.74387,36.95128,3,2
4.5,395.91711,0.05072,0.76081,37.51204,3,2
4.6,401.35794,0.05183,0.77744,38.02755,3,2
4.7,406.42755,0.05293,0.79394,38.50788,3,2
4.8,411.51755,0.05404,0.81062,38.99014,3,2
4.9,416.45282,0.05516,0.82744,39.45774,3,2
5,421.04419,0.05627,0.84406,39.89276,3,2
5.1,425.45694,0.05737,0.86062,40.31086,3,2
5.2,429.26749,0.05849,0.87731,40.6719,3,2
5.3,433.28915,0.05961,0.89412,41.05294,3,2
5.4,436.569,0.06071,0.91069,41.36369,3,2
5.5,439.82159,0.06181,0.92719,41.67187,3,2
5.6,442.68323,0.06294,0.94406,41.943,3,2
5.7,445.21307,0.06405,0.96075,42.1827,3,2
5.8,447.48477,0.06515,0.97731,42.39793,3,2
5.9,449.29251,0.06626,0.99394,42.56921,3,2
6,451.12869,0.06738,1.01069,42.74319,3,2
6.1,452.42886,0.0685,1.02744,42.86637,3,2
6.2,453.24335,0.0696,1.04406,42.94354,3,2
6.3,453.853,0.0707,1.0605,43.0013,3,2
6.4,454.45691,0.07183,1.0775,43.05853,3,2
6.5,454.25977,0.07293,1.094,43.03984,3,2
6.6,453.5838,0.07403,1.1105,42.9758,3,2
6.7,452.95508,0.07516,1.12737,42.91623,3,2
6.8,452.06537,0.07627,1.144,42.83193,3,2
6.9,450.76349,0.07737,1.16062,42.70858,3,2
7,448.7262,0.07848,1.17719,42.51556,3,2
7.1,447.17249,0.07959,1.19387,42.36835,3,2
7.2,445.1824,0.08072,1.21081,42.17979,3,2
7.3,442.67773,0.08182,1.22737,41.94248,3,2
7.4,440.02979,0.08292,1.24387,41.69159,3,2
7.5,437.50363,0.08405,1.26081,41.45225,3,2
7.6,434.5567,0.08516,1.27737,41.17303,3,2
7.7,431.76096,0.08627,1.294,40.90815,3,2
7.8,428.85779,0.08737,1.31056,40.63308,3,2
7.9,426.04129,0.08849,1.32737,40.36622,3,2
8,422.87506,0.08961,1.34412,40.06623,3,2
8.1,420.07413,0.0907,1.36056,39.80085,3,2
8.2,417.03204,0.09182,1.37731,39.51262,3,2
8.3,414.32321,0.09294,1.39412,39.25597,3,2
8.4,411.5141,0.09404,1.41062,38.98981,3,2
8.5,408.92862,0.09515,1.42725,38.74485,3,2
8.6,406.3989,0.09627,1.44406,38.50516,3,2
8.7,404.10226,0.09738,1.46069,38.28756,3,2
8.8,401.75696,0.09849,1.47737,38.06535,3,2
8.9,399.58615,0.0996,1.494,37.85967,3,2
9,397.47968,0.10072,1.51075,37.66009,3,2
9.1,395.41925,0.10183,1.52744,37.46487,3,2
9.2,393.46878,0.10292,1.54387,37.28007,3,2
9.3,391.4646,0.10404,1.56056,37.09018,3,2
9.4,389.72052,0.10517,1.5775,36.92493,3,2
9.5,387.63202,0.10626,1.59394,36.72705,3,2
9.6,385.25262,0.10737,1.61056,36.50161,3,2
9.7,382.3306,0.10849,1.62737,36.22476,3,2
9.794,268.89777,0.10954,1.64312,25.47731,3,2
0,13.20918,0,0,1.30307,2,2
0.1,18.46273,0.0009,0.0135,1.82132,2,2
0.2,32.89581,0.0022,0.03294,3.24512,2,2
0.3,43.61704,0.00332,0.04981,4.30276,2,2
0.4,54.50146,0.00445,0.06669,5.37649,2,2
0.5,65.07481,0.00556,0.08337,6.41953,2,2
0.6,75.45148,0.00667,0.1,7.44318,2,2
0.7,85.87734,0.00777,0.11662,8.47167,2,2
0.8,96.28039,0.00889,0.13331,9.49792,2,2
0.9,106.45786,0.01,0.15006,10.50191,2,2
1,116.47193,0.01111,0.16662,11.48978,2,2
1.1,126.58058,0.01221,0.18312,12.48699,2,2
1.2,136.4227,0.01334,0.20006,13.4579,2,2
1.3,146.54768,0.01444,0.21662,14.45671,2,2
1.4,155.97522,0.01555,0.23319,15.38672,2,2
1.5,165.3101,0.01666,0.24987,16.3076,2,2
1.6,175.11952,0.01778,0.26675,17.27528,2,2
1.7,184.45082,0.01889,0.28337,18.1958,2,2
1.8,193.59955,0.01999,0.29987,19.09831,2,2
1.9,202.57393,0.02111,0.31669,19.98362,2,2
2,211.57663,0.02222,0.33337,20.87172,2,2
2.1,220.39351,0.02333,0.35,21.74149,2,2
2.2,211.01465,0.02444,0.36662,20.81628,2,2
2.3,221.27386,0.02555,0.38331,21.82834,2,2
2.4,230.65775,0.02667,0.40006,22.75404,2,2
2.5,239.62131,0.02777,0.41662,23.63829,2,2
2.6,248.23558,0.02887,0.43312,24.48807,2,2
2.7,256.86938,0.03,0.45006,25.33978,2,2
2.8,265.16501,0.03111,0.46669,26.15813,2,2
2.9,273.03543,0.03222,0.48331,26.93454,2,2
3,281.38745,0.03333,0.5,27.75845,2,2
3.1,289.2319,0.03445,0.51675,28.5323,2,2
3.2,296.92401,0.03555,0.53331,29.29111,2,2
3.3,304.67288,0.03666,0.54994,30.05553,2,2
3.4,312.00735,0.03777,0.56662,30.77906,2,2
3.5,319.42789,0.0389,0.58344,31.51109,2,2
3.6,326.66223,0.04,0.6,32.22474,2,2
3.7,333.26883,0.0411,0.6165,32.87648,2,2
3.8,340.57089,0.04222,0.63337,33.59681,2,2
3.9,347.13574,0.04334,0.65006,34.24443,2,2
4,353.62347,0.04444,0.66656,34.88443,2,2
4.1,360.22327,0.04555,0.68319,35.53549,2,2
4.2,366.26099,0.04667,0.7,36.1311,2,2
4.3,372.51938,0.04778,0.71675,36.74848,2,2
4.4,378.26013,0.04889,0.73331,37.3148,2,2
4.5,383.89627,0.04999,0.74987,37.8708,2,2
4.6,389.78757,0.05112,0.76681,38.45197,2,2
4.7,394.86121,0.05222,0.78331,38.95247,2,2
4.8,399.87531,0.05332,0.79987,39.44711,2,2
4.9,404.78568,0.05445,0.81675,39.93151,2,2
5,409.75739,0.05556,0.83337,40.42196,2,2
5.1,414.16888,0.05667,0.85006,40.85714,2,2
5.2,418.51526,0.05777,0.86656,41.28591,2,2
5.3,422.65042,0.05889,0.88331,41.69384,2,2
5.4,426.20663,0.06001,0.90019,42.04465,2,2
5.5,429.90247,0.06111,0.91662,42.40924,2,2
5.6,433.24759,0.06221,0.93319,42.73923,2,2
5.7,436.32794,0.06334,0.95012,43.0431,2,2
5.8,439.03329,0.06445,0.96669,43.30998,2,2
5.9,441.56158,0.06555,0.98331,43.55939,2,2
6,443.79364,0.06667,1,43.77958,2,2
6.1,445.80322,0.06777,1.01662,43.97783,2,2
6.2,447.5798,0.06889,1.03337,44.15308,2,2
6.3,448.85281,0.07,1.05,44.27866,2,2
6.4,449.91647,0.07111,1.06669,44.38359,2,2
6.5,450.84433,0.07223,1.08344,44.47512,2,2
6.6,451.2384,0.07333,1.1,44.514,2,2
6.7,451.47733,0.07444,1.11656,44.53757,2,2
6.8,451.66061,0.07556,1.13337,44.55565,2,2
6.9,451.10538,0.07667,1.15,44.50087,2,2
7,450.51727,0.07777,1.16662,44.44286,2,2
7.1,449.61505,0.07887,1.18312,44.35386,2,2
7.2,448.672,0.08,1.20006,44.26083,2,2
7.3,447.27673,0.08112,1.21675,44.12318,2,2
7.4,445.67883,0.08222,1.23325,43.96555,2,2
7.5,444.15976,0.08333,1.25,43.8157,2,2
7.6,442.23303,0.08445,1.26681,43.62563,2,2
7.7,440.14273,0.08555,1.28325,43.41943,2,2
7.8,437.94293,0.08666,1.29994,43.20242,2,2
7.9,435.65942,0.08778,1.31675,42.97715,2,2
8,433.16739,0.08889,1.33337,42.73132,2,2
8.1,431.10553,0.09001,1.35012,42.52792,2,2
8.2,428.54962,0.0911,1.3665,42.27578,2,2
8.3,426.09698,0.09222,1.38331,42.03384,2,2
8.4,423.86041,0.09334,1.40012,41.8132,2,2
8.5,421.42603,0.09444,1.41656,41.57305,2,2
8.6,418.94666,0.09555,1.43325,41.32846,2,2
8.7,416.71194,0.09667,1.45012,41.10801,2,2
8.8,414.44977,0.09778,1.46669,40.88485,2,2
8.9,412.21933,0.0989,1.48344,40.66483,2,2
9,409.95172,0.1,1.49994,40.44113,2,2
9.1,407.87305,0.10112,1.51675,40.23607,2,2
9.2,406.00034,0.10222,1.53337,40.05133,2,2
9.3,403.94455,0.10332,1.54975,39.84853,2,2
9.4,402.15118,0.10445,1.56675,39.67162,2,2
9.5,400.15573,0.10556,1.58337,39.47477,2,2
9.6,398.54263,0.10666,1.59994,39.31564,2,2
9.7,396.46207,0.10777,1.61662,39.11039,2,2
9.8,395.01181,0.10889,1.63331,38.96733,2,2
9.9,393.40067,0.11001,1.65012,38.80839,2,2
10,391.78711,0.11111,1.66662,38.64922,2,2
10.1,390.41367,0.11221,1.68312,38.51373,2,2
10.2,389.01569,0.11335,1.70019,38.37582,2,2
10.3,387.8512,0.11445,1.71675,38.26094,2,2
10.4,386.37045,0.11555,1.73325,38.11487,2,2
10.5,385.04779,0.11667,1.75006,37.98439,2,2
10.6,384.08984,0.11778,1.76669,37.88989,2,2
10.7,382.7886,0.11889,1.78337,37.76153,2,2
10.8,381.76068,0.12,1.79994,37.66013,2,2
10.9,380.48605,0.12111,1.81662,37.53439,2,2
11,379.76141,0.12222,1.83337,37.4629,2,2
11.1,378.77097,0.12334,1.85012,37.36519,2,2
11.2,377.49701,0.12443,1.8665,37.23952,2,2
11.3,376.94852,0.12556,1.88344,37.18541,2,2
11.4,375.97247,0.12667,1.90006,37.08913,2,2
11.5,374.95905,0.12777,1.91656,36.98915,2,2
11.6,374.11499,0.12888,1.93325,36.90589,2,2
11.7,373.47079,0.13,1.95,36.84234,2,2
11.8,372.72018,0.13112,1.96675,36.76829,2,2
11.9,372.07773,0.13222,1.98331,36.70491,2,2
12,371.22598,0.13332,1.99987,36.62089,2,2
12.1,370.54593,0.13445,2.01681,36.55381,2,2
12.2,369.9906,0.13555,2.03331,36.49902,2,2
12.3,369.11465,0.13666,2.04987,36.41261,2,2
12.4,368.81934,0.13778,2.06675,36.38348,2,2
12.5,367.98691,0.13889,2.08337,36.30136,2,2
12.6,367.3421,0.14,2.10006,36.23775,2,2
12.7,366.98566,0.14111,2.11669,36.20259,2,2
12.8,366.25122,0.14222,2.13331,36.13014,2,2
12.9,365.85239,0.14334,2.15012,36.09079,2,2
13,365.42233,0.14444,2.16662,36.04837,2,2
13.1,364.93762,0.14554,2.18312,36.00055,2,2
13.2,364.54666,0.14668,2.20019,35.96199,2,2
13.3,364.07819,0.14777,2.21662,35.91577,2,2
13.4,363.59396,0.14889,2.23331,35.868,2,2
13.5,363.05554,0.15,2.25,35.81489,2,2
13.6,362.78967,0.15111,2.26669,35.78866,2,2
13.7,362.26434,0.15222,2.28331,35.73684,2,2
13.8,362.15213,0.15333,2.29994,35.72577,2,2
13.9,361.77368,0.15445,2.31669,35.68843,2,2
14,361.22873,0.15556,2.33344,35.63468,2,2
14.1,360.92609,0.15666,2.34994,35.60482,2,2
14.2,360.20093,0.15777,2.36656,35.53329,2,2
14.3,360.37396,0.1589,2.38344,35.55036,2,2
14.4,360.02155,0.16,2.4,35.51559,2,2
14.5,359.62601,0.16111,2.41669,35.47657,2,2
14.6,359.38669,0.16222,2.43325,35.45296,2,2
14.7,359.17331,0.16334,2.45006,35.43192,2,2
14.8,358.81793,0.16445,2.46675,35.39685,2,2
14.9,358.45059,0.16555,2.48325,35.36062,2,2
15,358.14816,0.16667,2.5,35.33078,2,2
15.1,358.13879,0.16779,2.51681,35.32986,2,2
15.2,357.8219,0.16888,2.53325,35.2986,2,2
15.3,357.34259,0.17,2.54994,35.25132,2,2
15.4,357.37299,0.17112,2.56675,35.25431,2,2
15.5,357.28802,0.17222,2.58331,35.24593,2,2
15.6,357.03146,0.17334,2.60006,35.22062,2,2
15.7,356.814,0.17444,2.61656,35.19917,2,2
15.8,356.57672,0.17556,2.63337,35.17576,2,2
15.9,356.48349,0.17668,2.65019,35.16656,2,2
16,356.20538,0.17777,2.6665,35.13913,2,2
16.1,355.94867,0.17888,2.68319,35.11381,2,2
16.2,355.88715,0.18001,2.70012,35.10774,2,2
16.3,355.75842,0.1811,2.71656,35.09504,2,2
16.4,355.61142,0.18222,2.73337,35.08054,2,2
16.5,355.31317,0.18332,2.74987,35.05112,2,2
16.6,355.19946,0.18445,2.76669,35.0399,2,2
16.7,355.30099,0.18555,2.78331,35.04992,2,2
16.8,355.23471,0.18665,2.79981,35.04338,2,2
16.9,355.06549,0.18778,2.81675,35.02668,2,2
17,355.15912,0.1889,2.8335,35.03592,2,2
17.1,355.00958,0.19,2.84994,35.02117,2,2
17.2,354.93845,0.19111,2.86662,35.01415,2,2
17.3,354.7728,0.19222,2.88337,34.99781,2,2
17.4,354.65131,0.19334,2.90006,34.98582,2,2
17.5,354.53952,0.19445,2.91669,34.9748,2,2
17.6,354.35544,0.19555,2.93319,34.95664,2,2
17.7,354.4017,0.19667,2.95012,34.9612,2,2
17.8,354.3812,0.19778,2.96675,34.95918,2,2
17.9,354.08203,0.19888,2.98319,34.92966,2,2
18,354.18552,0.2,3,34.93988,2,2
18.1,354.30933,0.20112,3.01675,34.95209,2,2
18.2,354.32388,0.20222,3.03331,34.95353,2,2
18.3,354.31772,0.20333,3.05,34.95292,2,2
18.4,354.11469,0.20444,3.06662,34.93289,2,2
18.5,354.20459,0.20556,3.08344,34.94176,2,2
18.6,354.40112,0.20667,3.10012,34.96114,2,2
18.7,354.14804,0.20777,3.1165,34.93618,2,2
18.8,354.0054,0.2089,3.13344,34.92211,2,2
18.9,354.30981,0.21,3.15006,34.95214,2,2
19,354.09338,0.2111,3.16656,34.93079,2,2
19.1,354.21976,0.21222,3.18325,34.94325,2,2
19.2,354.29492,0.21333,3.2,34.95067,2,2
19.3,354.26031,0.21445,3.21669,34.94725,2,2
19.4,354.25177,0.21556,3.23344,34.94641,2,2
19.5,354.11594,0.21666,3.24987,34.93301,2,2
19.6,354.35608,0.21778,3.26675,34.9567,2,2
19.7,354.71552,0.21889,3.28337,34.99216,2,2
19.8,354.44391,0.21999,3.29987,34.96537,2,2
19.9,354.47903,0.22112,3.31681,34.96883,2,2
20,354.78391,0.22222,3.33331,34.99891,2,2
20.1,354.55096,0.22334,3.35006,34.97593,2,2
20.2,354.67593,0.22444,3.36662,34.98825,2,2
20.3,354.79019,0.22555,3.38325,34.99953,2,2
20.4,354.72858,0.22667,3.40012,34.99345,2,2
20.5,354.64011,0.22777,3.41656,34.98472,2,2
20.6,354.5957,0.22888,3.43319,34.98034,2,2
20.7,354.95486,0.23001,3.45019,35.01577,2,2
20.8,355.0546,0.23111,3.46669,35.02561,2,2
20.9,355.23776,0.23222,3.48331,35.04368,2,2
21,355.25262,0.23333,3.5,35.04514,2,2
21.1,355.27579,0.23445,3.51669,35.04743,2,2
21.2,355.54224,0.23556,3.53337,35.07372,2,2
21.3,355.48022,0.23666,3.54994,35.0676,2,2
21.4,355.60043,0.23778,3.56669,35.07946,2,2
21.5,355.79944,0.2389,3.58344,35.09909,2,2
21.6,355.95145,0.24,3.6,35.11408,2,2
21.7,355.6413,0.2411,3.61656,35.08348,2,2
21.8,356.09085,0.24222,3.63337,35.12783,2,2
21.9,355.95712,0.24334,3.65006,35.11464,2,2
22,356.16428,0.24445,3.66669,35.13508,2,2
22.1,356.20453,0.24555,3.68325,35.13905,2,2
22.2,356.32016,0.24667,3.7,35.15046,2,2
22.3,356.52975,0.24779,3.71681,35.17113,2,2
22.4,356.4035,0.24888,3.73325,35.15868,2,2
22.5,356.61993,0.25,3.74994,35.18003,2,2
22.6,356.85858,0.25112,3.76681,35.20357,2,2
22.7,356.96448,0.25222,3.78325,35.21402,2,2
22.8,357.05511,0.25333,3.79994,35.22296,2,2
22.9,357.18408,0.25445,3.81675,35.23568,2,2
23,357.18613,0.25555,3.83331,35.23588,2,2
23.1,357.39673,0.25667,3.85006,35.25666,2,2
23.2,357.34622,0.25777,3.86656,35.25167,2,2
23.3,357.51184,0.25889,3.88331,35.26801,2,2
23.4,357.67212,0.26001,3.90012,35.28382,2,2
23.5,357.65292,0.2611,3.91656,35.28193,2,2
23.6,357.75143,0.26221,3.93319,35.29165,2,2
23.7,357.83633,0.26334,3.95012,35.30002,2,2
23.8,357.59247,0.26445,3.96669,35.27597,2,2
23.9,357.08133,0.26555,3.98331,35.22554,2,2
23.94,259.44031,0.266,3.98994,25.5934,2,2
0,1.12807,0.00015,0.00225,0.11753,1,2
0.1,11.51375,0.00157,0.0235,1.19961,1,2
0.2,22.12353,0.00271,0.04062,2.30504,1,2
0.3,32.32849,0.00383,0.0575,3.36829,1,2
0.4,42.56328,0.00496,0.07437,4.43465,1,2
0.5,52.61452,0.00607,0.09106,5.48188,1,2
0.6,62.8707,0.00717,0.10762,6.55046,1,2
0.7,72.98702,0.00829,0.12431,7.60448,1,2
0.8,82.90527,0.0094,0.14106,8.63786,1,2
0.9,92.67941,0.01051,0.15762,9.65622,1,2
1,102.30136,0.01161,0.17419,10.65872,1,2
1.1,111.78121,0.01273,0.19094,11.64642,1,2
1.2,121.44774,0.01385,0.20775,12.65357,1,2
1.3,130.98102,0.01496,0.22437,13.64684,1,2
1.4,140.28746,0.01605,0.24075,14.61647,1,2
1.5,149.53484,0.01718,0.25769,15.57995,1,2
1.6,158.66304,0.01829,0.27437,16.53102,1,2
1.7,167.75116,0.0194,0.291,17.4779,1,2
1.8,176.74176,0.0205,0.3075,18.41463,1,2
1.9,185.30188,0.02162,0.32437,19.3065,1,2
2,194.16316,0.02274,0.34106,20.22975,1,2
2.1,202.70074,0.02384,0.35762,21.11928,1,2
2.2,211.17206,0.02495,0.37431,22.0019,1,2
2.3,201.01187,0.02607,0.39106,20.94332,1,2
2.4,210.75737,0.02717,0.40762,21.95869,1,2
2.5,219.75769,0.02829,0.42431,22.89643,1,2
2.6,228.28493,0.0294,0.441,23.78488,1,2
2.7,236.84341,0.03052,0.45775,24.67659,1,2
2.8,245.09648,0.03162,0.47437,25.53647,1,2
2.9,253.13699,0.03273,0.49094,26.3742,1,2
3,261.15976,0.03385,0.50775,27.21009,1,2
3.1,268.91058,0.03496,0.52437,28.01765,1,2
3.2,276.5199,0.03607,0.54106,28.81046,1,2
3.3,283.90012,0.03717,0.5575,29.5794,1,2
3.4,291.38928,0.03829,0.57437,30.35969,1,2
3.5,298.68289,0.03941,0.59112,31.11961,1,2
3.6,305.57932,0.0405,0.60756,31.83814,1,2
3.7,312.54779,0.04162,0.62431,32.56418,1,2
3.8,319.13342,0.04274,0.64106,33.25034,1,2
3.9,325.65823,0.04384,0.65762,33.93015,1,2
4,332.0007,0.04495,0.67431,34.59097,1,2
4.1,338.27243,0.04606,0.69094,35.24442,1,2
4.2,344.44196,0.04718,0.70775,35.88722,1,2
4.3,350.44882,0.04829,0.72437,36.51307,1,2
4.4,356.08057,0.04939,0.74081,37.09984,1,2
4.5,361.52222,0.05052,0.75775,37.6668,1,2
4.6,367.0755,0.05163,0.77444,38.2454,1,2
4.7,371.92569,0.05273,0.79094,38.75074,1,2
4.8,377.18317,0.05384,0.80756,39.29851,1,2
4.9,382.0632,0.05496,0.82444,39.80696,1,2
5,386.42825,0.05607,0.84112,40.26175,1,2
5.1,390.51285,0.05717,0.85762,40.68732,1,2
5.2,394.81763,0.05828,0.87425,41.13583,1,2
5.3,398.59024,0.05941,0.89112,41.5289,1,2
5.4,402.31693,0.06051,0.90769,41.91718,1,2
5.5,405.41022,0.06162,0.92425,42.23947,1,2
5.6,408.66156,0.06273,0.941,42.57822,1,2
5.7,411.45566,0.06385,0.95781,42.86934,1,2
5.8,413.92007,0.06496,0.97437,43.12611,1,2
5.9,416.25272,0.06606,0.99087,43.36914,1,2
6,418.15262,0.06718,1.00769,43.56709,1,2
6.1,419.93262,0.0683,1.02444,43.75255,1,2
6.2,421.23776,0.0694,1.04106,43.88853,1,2
6.3,422.15967,0.0705,1.0575,43.98458,1,2
6.4,422.84521,0.07163,1.07444,44.05601,1,2
6.5,423.09518,0.07274,1.09106,44.08206,1,2
6.6,423.08063,0.07383,1.1075,44.08054,1,2
6.7,422.95322,0.07495,1.12431,44.06726,1,2
6.8,422.33713,0.07607,1.14112,44.00307,1,2
6.9,421.43362,0.07717,1.15762,43.90894,1,2
7,420.05209,0.07829,1.17431,43.765,1,2
7.1,418.66229,0.07939,1.19087,43.6202,1,2
7.2,417.1582,0.08052,1.20781,43.46349,1,2
7.3,414.99512,0.08162,1.22437,43.23811,1,2
7.4,413.12173,0.08272,1.24087,43.04293,1,2
7.5,410.63464,0.08385,1.25781,42.7838,1,2
7.6,408.3884,0.08496,1.27437,42.54976,1,2
7.7,405.78461,0.08606,1.29094,42.27848,1,2
7.8,403.32886,0.08717,1.30756,42.02261,1,2
7.9,400.80487,0.08829,1.32431,41.75964,1,2
8,398.25513,0.08941,1.34112,41.49398,1,2
8.1,395.27505,0.09051,1.35762,41.18349,1,2
8.2,392.39066,0.09162,1.37425,40.88297,1,2
8.3,390.10007,0.09274,1.39112,40.64431,1,2
8.4,387.56131,0.09384,1.40762,40.3798,1,2
8.5,385.01248,0.09495,1.42425,40.11424,1,2
8.6,382.63168,0.09607,1.44106,39.86618,1,2
8.7,380.55429,0.09718,1.45769,39.64974,1,2
8.8,378.45834,0.0983,1.47444,39.43137,1,2
8.9,376.1879,0.0994,1.49094,39.19481,1,2
9,374.21149,0.10051,1.50762,38.98889,1,2
9.1,372.57654,0.10163,1.52444,38.81855,1,2
9.2,370.34558,0.10273,1.54094,38.58611,1,2
9.3,368.58688,0.10383,1.5575,38.40287,1,2
9.4,367.07703,0.10496,1.57444,38.24556,1,2
9.5,365.2467,0.10607,1.591,38.05486,1,2
9.6,363.82758,0.10717,1.60756,37.907,1,2
9.7,362.01624,0.10829,1.62437,37.71827,1,2
9.8,360.54886,0.1094,1.64106,37.56539,1,2
9.9,352.10947,0.11052,1.65775,36.68609,1,2
9.916,236.69992,0.1107,1.6605,24.66164,1,2
0,1.31846,0.00031,0.00462,0.11784,1,1
0.1,20.78802,0.00176,0.02644,1.8579,1,1
0.2,38.1772,0.0029,0.04344,3.41203,1,1
0.3,54.16115,0.00402,0.06025,4.84057,1,1
0.4,69.8774,0.00513,0.077,6.24519,1,1
0.5,85.68314,0.00625,0.09375,7.6578,1,1
0.6,101.22495,0.00736,0.11037,9.04683,1,1
0.7,116.62086,0.00846,0.12694,10.42281,1,1
0.8,131.96512,0.00958,0.14375,11.79418,1,1
0.9,147.38057,0.01069,0.16037,13.17192,1,1
1,162.39703,0.0118,0.17694,14.51399,1,1
1.1,176.86313,0.01291,0.19362,15.80688,1,1
1.2,191.80629,0.01403,0.21044,17.1424,1,1
1.3,206.27762,0.01513,0.22694,18.43575,1,1
1.4,220.66052,0.01623,0.2435,19.7212,1,1
1.5,234.91554,0.01735,0.26031,20.99522,1,1
1.6,248.85875,0.01847,0.27706,22.24137,1,1
1.7,262.60916,0.01957,0.29362,23.4703,1,1
1.8,257.72577,0.02068,0.31019,23.03385,1,1
1.9,269.15308,0.0218,0.327,24.05515,1,1
2,282.90146,0.02292,0.34375,25.28389,1,1
2.1,296.93781,0.02402,0.36031,26.53837,1,1
2.2,310.20264,0.02512,0.37681,27.72389,1,1
2.3,323.55936,0.02625,0.39375,28.91763,1,1
2.4,336.50958,0.02735,0.41031,30.07504,1,1
2.5,349.12732,0.02846,0.42687,31.20273,1,1
2.6,361.59332,0.02957,0.44362,32.31686,1,1
2.7,373.95645,0.03069,0.46037,33.42179,1,1
2.8,386.26361,0.0318,0.477,34.52173,1,1
2.9,398.08246,0.0329,0.49356,35.57802,1,1
3,409.87701,0.03402,0.51031,36.63214,1,1
3.1,421.20731,0.03514,0.52706,37.64477,1,1
3.2,432.78983,0.03625,0.54369,38.67994,1,1
3.3,443.43149,0.03735,0.56025,39.63102,1,1
3.4,454.25934,0.03846,0.57694,40.59874,1,1
3.5,465.23331,0.03959,0.59381,41.57952,1,1
3.6,475.28363,0.04068,0.61025,42.47776,1,1
3.7,485.51196,0.04179,0.62681,43.3919,1,1
3.8,495.49402,0.04292,0.64381,44.28403,1,1
3.9,505.17175,0.04402,0.66031,45.14896,1,1
4,514.34924,0.04513,0.67694,45.96919,1,1
4.1,523.63049,0.04624,0.69356,46.79868,1,1
4.2,532.78723,0.04736,0.71037,47.61705,1,1
4.3,541.38013,0.04847,0.72712,48.38503,1,1
4.4,549.68475,0.04957,0.74356,49.12725,1,1
4.5,557.59729,0.0507,0.76044,49.83442,1,1
4.6,565.39691,0.05181,0.77712,50.53149,1,1
4.7,572.93585,0.05291,0.79369,51.20528,1,1
4.8,580.01019,0.05402,0.81025,51.83754,1,1
4.9,586.97101,0.05513,0.82694,52.45965,1,1
5,593.60126,0.05625,0.84375,53.05222,1,1
5.1,600.02179,0.05735,0.86031,53.62604,1,1
5.2,606.04675,0.05845,0.87681,54.16451,1,1
5.3,611.828,0.05959,0.89381,54.68121,1,1
5.4,617.11041,0.06069,0.91037,55.15331,1,1
5.5,622.32806,0.0618,0.92694,55.61963,1,1
5.6,627.16425,0.06291,0.94369,56.05186,1,1
5.7,631.70349,0.06402,0.96037,56.45755,1,1
5.8,636.16998,0.06514,0.97706,56.85673,1,1
5.9,639.70575,0.06624,0.99362,57.17274,1,1
6,643.16913,0.06735,1.01031,57.48227,1,1
6.1,646.48395,0.06847,1.02712,57.77853,1,1
6.2,649.37695,0.06958,1.04369,58.03709,1,1
6.3,651.9649,0.07068,1.06019,58.26838,1,1
6.4,654.42023,0.0718,1.07706,58.48782,1,1
6.5,656.19568,0.07291,1.09369,58.6465,1,1
6.6,657.89166,0.07402,1.11031,58.79807,1,1
6.7,659.10229,0.07512,1.12687,58.90627,1,1
6.8,659.95453,0.07625,1.14369,58.98244,1,1
6.9,660.55426,0.07736,1.16044,59.03604,1,1
7,660.79089,0.07846,1.17694,59.05719,1,1
7.1,660.55011,0.07957,1.19362,59.03567,1,1
7.2,660.28009,0.0807,1.21044,59.01154,1,1
7.3,659.3634,0.0818,1.227,58.92961,1,1
7.4,658.15265,0.0829,1.24356,58.8214,1,1
7.5,656.9389,0.08402,1.26037,58.71292,1,1
7.6,654.64929,0.08514,1.27706,58.50829,1,1
7.7,652.21417,0.08625,1.29375,58.29066,1,1
7.8,649.72327,0.08735,1.31031,58.06804,1,1
7.9,646.75116,0.08847,1.327,57.80241,1,1
8,643.09601,0.08959,1.34381,57.47573,1,1
8.1,639.47656,0.09069,1.36031,57.15225,1,1
8.2,635.49994,0.09179,1.37681,56.79685,1,1
8.3,491.08154,0.09292,1.39387,43.88967,1,1
8.306,392.50665,0.093,1.39494,35.07969,1,1
0,1.17805,0.00019,0.00287,0.10853,2,1
0.1,8.32128,0.00161,0.02419,0.76658,2,1
0.2,12.43475,0.00275,0.04131,1.14553,2,1
0.3,28.62568,0.00388,0.05819,2.6371,2,1
0.4,44.30292,0.005,0.075,4.08134,2,1
0.5,60.02262,0.00611,0.09169,5.52949,2,1
0.6,75.31099,0.00723,0.10844,6.93791,2,1
0.7,90.77457,0.00833,0.12494,8.36247,2,1
0.8,105.83643,0.00945,0.14169,9.75002,2,1
0.9,120.91101,0.01056,0.15837,11.13874,2,1
1,135.69191,0.01166,0.17494,12.50041,2,1
1.1,150.4281,0.01277,0.19156,13.85796,2,1
1.2,165.03319,0.01389,0.20837,15.20343,2,1
1.3,179.77815,0.015,0.225,16.56178,2,1
1.4,194.2677,0.0161,0.24156,17.89661,2,1
1.5,208.18349,0.01722,0.25831,19.17858,2,1
1.6,222.21364,0.01834,0.27506,20.47109,2,1
1.7,236.28485,0.01944,0.29162,21.76738,2,1
1.8,249.72224,0.02055,0.30819,23.00527,2,1
1.9,263.50284,0.02166,0.32494,24.27479,2,1
2,276.64673,0.02278,0.34169,25.48565,2,1
2.1,289.54391,0.02389,0.35837,26.67378,2,1
2.2,280.10989,0.02499,0.37487,25.80469,2,1
2.3,295.53763,0.02612,0.39175,27.22595,2,1
2.4,309.11664,0.02722,0.40837,28.47689,2,1
2.5,322.1416,0.02832,0.42487,29.6768,2,1
2.6,334.92697,0.02944,0.44162,30.85463,2,1
2.7,347.93765,0.03056,0.45844,32.05322,2,1
2.8,360.0463,0.03167,0.47506,33.1687,2,1
2.9,372.15121,0.03277,0.49162,34.28386,2,1
3,384.08957,0.03389,0.50831,35.38366,2,1
3.1,395.93961,0.035,0.52506,36.47532,2,1
3.2,407.53983,0.03611,0.54169,37.54398,2,1
3.3,418.9624,0.03722,0.55831,38.59626,2,1
3.4,429.93481,0.03833,0.57494,39.60708,2,1
3.5,441.10556,0.03945,0.59175,40.63617,2,1
3.6,451.8129,0.04055,0.60831,41.62256,2,1
3.7,462.00418,0.04165,0.62481,42.56142,2,1
3.8,472.66675,0.04279,0.64181,43.54369,2,1
3.9,482.83719,0.04389,0.65831,44.48063,2,1
4,492.60162,0.045,0.67494,45.38016,2,1
4.1,502.36313,0.0461,0.69156,46.27942,2,1
4.2,511.86319,0.04722,0.70837,47.1546,2,1
4.3,521.13263,0.04834,0.72512,48.00853,2,1
4.4,529.80103,0.04944,0.74156,48.8071,2,1
4.5,538.75922,0.05056,0.75837,49.63236,2,1
4.6,547.43018,0.05167,0.77512,50.43116,2,1
4.7,555.52069,0.05277,0.79162,51.17648,2,1
4.8,563.37158,0.05388,0.80825,51.89973,2,1
4.9,571.37695,0.055,0.825,52.63721,2,1
5,578.9884,0.05611,0.84169,53.33841,2,1
5.1,585.95703,0.05722,0.85837,53.98038,2,1
5.2,592.78668,0.05832,0.87481,54.60955,2,1
5.3,599.79919,0.05945,0.89175,55.25557,2,1
5.4,606.19714,0.06056,0.90837,55.84497,2,1
5.5,612.11267,0.06166,0.92487,56.38993,2,1
5.6,618.02393,0.06278,0.94169,56.93449,2,1
5.7,623.75348,0.06389,0.95837,57.46232,2,1
5.8,628.95703,0.065,0.97506,57.94169,2,1
5.9,633.94293,0.06611,0.99169,58.40101,2,1
6,638.90729,0.06722,1.00825,58.85834,2,1
6.1,643.38403,0.06834,1.02512,59.27076,2,1
6.2,647.61389,0.06945,1.04169,59.66043,2,1
6.3,651.3775,0.07055,1.05819,60.00714,2,1
6.4,655.23572,0.07167,1.07512,60.36258,2,1
6.5,658.57489,0.07278,1.09169,60.67019,2,1
6.6,661.65552,0.07389,1.10837,60.95399,2,1
6.7,664.77161,0.075,1.12494,61.24105,2,1
6.8,667.24512,0.07611,1.14169,61.46892,2,1
6.9,669.74487,0.07723,1.15844,61.69921,2,1
7,671.86304,0.07833,1.17494,61.89434,2,1
7.1,673.57404,0.07944,1.19156,62.05196,2,1
7.2,675.30792,0.08056,1.20837,62.2117,2,1
7.3,676.99139,0.08167,1.22506,62.36678,2,1
7.4,678.2486,0.08277,1.24156,62.4826,2,1
7.5,679.12036,0.08389,1.25837,62.56291,2,1
7.6,679.82751,0.08501,1.27512,62.62806,2,1
7.7,680.35236,0.08611,1.29169,62.67641,2,1
7.8,680.52051,0.08722,1.30831,62.6919,2,1
7.9,680.93024,0.08833,1.32494,62.72964,2,1
8,680.69708,0.08945,1.34181,62.70816,2,1
8.1,680.37122,0.09056,1.35837,62.67814,2,1
8.2,679.93573,0.09165,1.37481,62.63802,2,1
8.3,679.46014,0.09279,1.39181,62.59421,2,1
8.4,678.58337,0.09389,1.40831,62.51344,2,1
8.5,677.33203,0.095,1.42494,62.39816,2,1
8.6,676.35083,0.09611,1.44162,62.30777,2,1
8.7,675.00433,0.09722,1.45831,62.18373,2,1
8.8,673.65747,0.09834,1.47512,62.05965,2,1
8.9,671.8092,0.09945,1.49175,61.88938,2,1
9,669.95593,0.10055,1.50831,61.71865,2,1
9.1,668.32648,0.10168,1.52519,61.56854,2,1
9.2,666.07471,0.10277,1.54162,61.3611,2,1
9.3,663.92902,0.10388,1.55825,61.16343,2,1
9.4,661.84601,0.105,1.575,60.97154,2,1
9.5,659.10101,0.10611,1.59162,60.71866,2,1
9.6,656.75952,0.10722,1.60831,60.50295,2,1
9.7,654.11603,0.10832,1.62475,60.25943,2,1
9.8,651.80951,0.10945,1.64169,60.04694,2,1
9.9,649.27667,0.11056,1.65844,59.81361,2,1
10,646.44049,0.11166,1.67487,59.55233,2,1
10.1,643.57336,0.11277,1.69162,59.2882,2,1
10.2,641.02167,0.1139,1.7085,59.05313,2,1
10.3,638.08051,0.115,1.725,58.78218,2,1
10.4,635.39832,0.11611,1.74162,58.53508,2,1
10.5,632.34827,0.11722,1.75837,58.2541,2,1
10.6,629.56146,0.11833,1.775,57.99737,2,1
10.7,626.82141,0.11945,1.79175,57.74495,2,1
10.8,623.91425,0.12055,1.80825,57.47713,2,1
10.9,620.94818,0.12167,1.825,57.20389,2,1
11,618.23547,0.12278,1.84175,56.95398,2,1
11.1,615.3913,0.12388,1.85825,56.69197,2,1
11.2,612.46387,0.125,1.87494,56.42228,2,1
11.3,609.789,0.12612,1.89175,56.17587,2,1
11.4,607.33447,0.12722,1.90837,55.94975,2,1
11.5,604.63721,0.12834,1.92506,55.70126,2,1
11.6,601.78137,0.12944,1.94156,55.43818,2,1
11.7,599.42786,0.13056,1.95837,55.22136,2,1
11.8,596.85217,0.13167,1.97512,54.98408,2,1
11.9,594.3078,0.13277,1.9915,54.74968,2,1
12,591.9646,0.13389,2.00837,54.53382,2,1
12.1,589.77466,0.13501,2.02512,54.33208,2,1
12.2,587.44916,0.13611,2.04162,54.11784,2,1
12.3,585.10712,0.13722,2.05831,53.90208,2,1
12.4,582.95184,0.13833,2.07494,53.70353,2,1
12.5,580.96289,0.13945,2.09181,53.52031,2,1
12.6,578.62286,0.14056,2.10844,53.30473,2,1
12.7,576.67828,0.14165,2.12481,53.12559,2,1
12.8,575.01184,0.14279,2.14181,52.97207,2,1
12.9,573.36084,0.1439,2.15844,52.81998,2,1
13,571.48486,0.14499,2.17487,52.64716,2,1
13.1,569.90424,0.14611,2.19162,52.50154,2,1
13.2,568.18091,0.14722,2.20837,52.34278,2,1
13.3,567.04657,0.14833,2.225,52.23829,2,1
13.4,565.22534,0.14945,2.24169,52.07051,2,1
13.5,563.79694,0.15055,2.25819,51.93892,2,1
13.6,562.65723,0.15167,2.27506,51.83392,2,1
13.7,561.47748,0.15278,2.29175,51.72524,2,1
13.8,559.70087,0.15388,2.30819,51.56157,2,1
13.9,558.23645,0.15501,2.32512,51.42667,2,1
13.954,384.52661,0.15562,2.33425,35.42392,2,1
0,1.25071,0.00031,0.00462,0.11878,3,1
0.1,9.10544,0.00173,0.02594,0.86473,3,1
0.2,21.81321,0.00287,0.04306,2.07157,3,1
0.3,37.50548,0.00399,0.05987,3.56184,3,1
0.4,53.03725,0.00511,0.07669,5.03687,3,1
0.5,68.88273,0.00623,0.09344,6.54169,3,1
0.6,84.44028,0.00734,0.11006,8.01917,3,1
0.7,99.2784,0.00844,0.12656,9.42833,3,1
0.8,114.72177,0.00956,0.14337,10.89496,3,1
0.9,130.0098,0.01067,0.16006,12.34684,3,1
1,144.7675,0.01177,0.17662,13.74836,3,1
1.1,159.67055,0.01288,0.19325,15.16368,3,1
1.2,174.51689,0.014,0.21006,16.57362,3,1
1.3,189.11894,0.01511,0.22669,17.96035,3,1
1.4,203.3903,0.01621,0.24319,19.31569,3,1
1.5,217.64319,0.01733,0.26,20.66926,3,1
1.6,231.98726,0.01845,0.27669,22.0315,3,1
1.7,245.9073,0.01955,0.29331,23.35346,3,1
1.8,259.23788,0.02066,0.30987,24.61945,3,1
1.9,273.07895,0.02177,0.32662,25.93391,3,1
2,286.63675,0.02289,0.34337,27.22148,3,1
2.1,272.93091,0.024,0.35994,25.91986,3,1
2.2,287.39731,0.0251,0.3765,27.29371,3,1
2.3,301.53085,0.02623,0.39344,28.63595,3,1
2.4,315.23849,0.02734,0.41006,29.93775,3,1
2.5,328.41501,0.02844,0.42656,31.1891,3,1
2.6,341.20938,0.02955,0.44331,32.40416,3,1
2.7,353.90082,0.03067,0.46006,33.60945,3,1
2.8,366.48441,0.03178,0.47669,34.8045,3,1
2.9,378.57831,0.03288,0.49325,35.95304,3,1
3,390.76126,0.034,0.51,37.11003,3,1
3.1,402.5495,0.03512,0.52675,38.22955,3,1
3.2,414.10254,0.03622,0.54337,39.32672,3,1
3.3,425.46353,0.03733,0.55994,40.40566,3,1
3.4,436.81421,0.03844,0.57662,41.48362,3,1
3.5,447.54315,0.03956,0.59344,42.50253,3,1
3.6,458.34927,0.04066,0.60994,43.52877,3,1
3.7,468.54977,0.04177,0.6265,44.4975,3,1
3.8,478.56238,0.0429,0.64344,45.44838,3,1
3.9,488.94739,0.044,0.66,46.43463,3,1
4,498.49033,0.04511,0.67662,47.34091,3,1
4.1,507.80481,0.04622,0.69325,48.22549,3,1
4.2,517.20978,0.04734,0.71006,49.11867,3,1
4.3,526.0733,0.04845,0.72675,49.96043,3,1
4.4,534.67047,0.04955,0.74319,50.77689,3,1
4.5,543.28754,0.05067,0.76006,51.59524,3,1
4.6,551.75775,0.05178,0.77675,52.39964,3,1
4.7,559.19775,0.05289,0.79331,53.1062,3,1
4.8,566.87671,0.054,0.80994,53.83546,3,1
4.9,574.19373,0.05511,0.82662,54.53035,3,1
5,581.22296,0.05622,0.84337,55.19791,3,1
5.1,587.888,0.05733,0.86,55.83088,3,1
5.2,594.20697,0.05843,0.87644,56.43098,3,1
5.3,600.50708,0.05957,0.8935,57.02929,3,1
5.4,606.19641,0.06067,0.91006,57.5696,3,1
5.5,611.59796,0.06177,0.92656,58.08258,3,1
5.6,617.0097,0.06289,0.94331,58.59652,3,1
5.7,622.086,0.064,0.96006,59.07861,3,1
5.8,626.60577,0.06511,0.97669,59.50785,3,1
5.9,630.97046,0.06622,0.99331,59.92236,3,1
6,635.06604,0.06733,1.00994,60.31131,3,1
6.1,638.82611,0.06845,1.02675,60.6684,3,1
6.2,642.32996,0.06956,1.04337,61.00115,3,1
6.3,645.36633,0.07066,1.05987,61.28951,3,1
6.4,648.5567,0.07178,1.07675,61.5925,3,1
6.5,651.15417,0.07289,1.09337,61.83918,3,1
6.6,653.56964,0.074,1.11,62.06857,3,1
6.7,655.55444,0.0751,1.12656,62.25706,3,1
6.8,657.68927,0.07622,1.14337,62.4598,3,1
6.9,659.35718,0.07734,1.16012,62.6182,3,1
7,660.53131,0.07844,1.17662,62.72971,3,1
7.1,661.82178,0.07955,1.19325,62.85226,3,1
7.2,662.95831,0.08067,1.21012,62.9602,3,1
7.3,663.54901,0.08178,1.22669,63.0163,3,1
7.4,664.1839,0.08288,1.24325,63.07659,3,1
7.5,664.46576,0.084,1.26006,63.10336,3,1
7.6,664.32581,0.08512,1.27675,63.09007,3,1
7.7,664.44385,0.08622,1.29337,63.10128,3,1
7.8,663.93854,0.08733,1.30994,63.05329,3,1
7.9,663.57574,0.08845,1.32669,63.01883,3,1
8,663.0802,0.08957,1.3435,62.97177,3,1
8.1,662.1441,0.09067,1.36,62.88287,3,1
8.2,661.19299,0.09176,1.37644,62.79255,3,1
8.3,660.19592,0.0929,1.3935,62.69786,3,1
8.4,658.98248,0.094,1.41,62.58262,3,1
8.5,657.43719,0.09511,1.42662,62.43586,3,1
8.6,655.92249,0.09622,1.44331,62.29202,3,1
8.7,654.38501,0.09733,1.46,62.146,3,1
8.8,652.60797,0.09845,1.47675,61.97724,3,1
8.9,650.66113,0.09956,1.49337,61.79235,3,1
9,648.52808,0.10067,1.51006,61.58978,3,1
9.1,646.83295,0.10179,1.52681,61.42879,3,1
9.2,644.62817,0.10289,1.54331,61.21941,3,1
9.3,642.2594,0.104,1.55994,60.99445,3,1
9.4,640.23438,0.10511,1.57669,60.80214,3,1
9.5,637.87769,0.10622,1.59331,60.57833,3,1
9.6,635.65295,0.10733,1.60994,60.36705,3,1
9.7,632.966,0.10843,1.62644,60.11187,3,1
9.8,630.58362,0.10956,1.64337,59.88562,3,1
9.9,628.46991,0.11067,1.66012,59.68488,3,1
10,625.87622,0.11177,1.67656,59.43856,3,1
10.1,623.54602,0.11289,1.69337,59.21727,3,1
10.2,621.27838,0.11401,1.71012,59.00191,3,1
10.3,618.82031,0.11511,1.72662,58.76847,3,1
10.4,616.47382,0.11622,1.74331,58.54563,3,1
10.5,613.74084,0.11734,1.76006,58.28609,3,1
10.6,611.52826,0.11845,1.77669,58.07596,3,1
10.7,609.12811,0.11956,1.79344,57.84802,3,1
10.8,606.67584,0.12065,1.80981,57.61513,3,1
10.9,604.57086,0.12178,1.82669,57.41523,3,1
11,602.42792,0.1229,1.84344,57.21171,3,1
11.1,600.02716,0.124,1.85994,56.98372,3,1
11.2,597.6712,0.1251,1.87656,56.75998,3,1
11.3,595.55328,0.12623,1.89344,56.55884,3,1
11.4,593.25073,0.12733,1.91,56.34017,3,1
11.5,591.10754,0.12845,1.92675,56.13663,3,1
11.6,588.5155,0.12955,1.94325,55.89047,3,1
11.7,502.14148,0.13067,1.96006,47.68765,3,1
11.708,387.50848,0.13077,1.9615,36.80112,3,1
0,1.22772,0.00017,0.00262,0.05943,4,1
0.1,19.70591,0.00157,0.02394,0.95391,4,1
0.2,52.71967,0.00269,0.041,2.55202,4,1
0.3,82.85551,0.00379,0.05781,4.01082,4,1
0.4,112.50735,0.0049,0.07469,5.44619,4,1
0.5,141.63841,0.00599,0.09137,6.85635,4,1
0.6,170.79485,0.00708,0.10794,8.26773,4,1
0.7,199.15886,0.00817,0.12462,9.64076,4,1
0.8,228.13443,0.00927,0.14137,11.04339,4,1
0.9,256.16034,0.01036,0.15794,12.40005,4,1
1,283.94983,0.01145,0.17456,13.74527,4,1
1.1,311.61377,0.01254,0.19125,15.08441,4,1
1.2,339.22717,0.01364,0.20806,16.4211,4,1
1.3,365.92535,0.01473,0.22462,17.71349,4,1
1.4,343.39838,0.01581,0.24112,16.62302,4,1
1.5,372.82831,0.01692,0.25806,18.04765,4,1
1.6,400.63931,0.01802,0.27475,19.39391,4,1
1.7,427.19714,0.0191,0.29131,20.6795,4,1
1.8,453.12167,0.02019,0.30787,21.93444,4,1
1.9,479.11197,0.02129,0.32469,23.19256,4,1
2,504.51212,0.02239,0.34137,24.42212,4,1
2.1,529.34338,0.02347,0.35787,25.62413,4,1
2.2,553.64191,0.02457,0.37462,26.80036,4,1
2.3,578.24646,0.02566,0.39137,27.9914,4,1
2.4,602.37128,0.02675,0.40794,29.15922,4,1
2.5,625.47845,0.02784,0.42462,30.27778,4,1
2.6,648.9068,0.02894,0.44131,31.41189,4,1
2.7,672.27252,0.03004,0.45806,32.54296,4,1
2.8,694.58594,0.03113,0.47469,33.6231,4,1
2.9,716.41248,0.03221,0.49119,34.67966,4,1
3,738.7713,0.03331,0.508,35.76199,4,1
3.1,760.68243,0.03441,0.52469,36.82265,4,1
3.2,781.85919,0.0355,0.54137,37.84777,4,1
3.3,802.20374,0.03658,0.55787,38.83259,4,1
3.4,823.21063,0.03769,0.57475,39.84948,4,1
3.5,843.42194,0.03878,0.59144,40.82786,4,1
3.6,862.7373,0.03986,0.60787,41.76286,4,1
3.7,881.77954,0.04096,0.62469,42.68465,4,1
3.8,901.12909,0.04206,0.64144,43.62131,4,1
3.9,919.32275,0.04314,0.65787,44.50202,4,1
4,937.13495,0.04424,0.67462,45.36426,4,1
4.1,954.88727,0.04533,0.69125,46.22361,4,1
4.2,972.02557,0.04643,0.70806,47.05323,4,1
4.3,988.5921,0.04752,0.72475,47.85517,4,1
4.4,1004.39581,0.0486,0.74119,48.62019,4,1
4.5,1020.10071,0.04971,0.75806,49.38042,4,1
4.6,1035.48499,0.0508,0.77475,50.12513,4,1
4.7,1049.63281,0.05189,0.79125,50.80999,4,1
4.8,1063.39954,0.05298,0.80787,51.4764,4,1
4.9,1077.2854,0.05409,0.82481,52.14858,4,1
5,1090.0874,0.05518,0.84144,52.76829,4,1
5.1,1102.42163,0.05626,0.858,53.36536,4,1
5.2,1113.52563,0.05735,0.87462,53.90287,4,1
5.3,1124.80334,0.05846,0.8915,54.4488,4,1
5.4,1135.16809,0.05954,0.908,54.95053,4,1
5.5,1144.35938,0.06063,0.92456,55.39545,4,1
5.6,1153.09558,0.06173,0.94137,55.81835,4,1
5.7,1161.70447,0.06282,0.95806,56.23508,4,1
5.8,1168.89697,0.06391,0.97469,56.58326,4,1
5.9,1175.76221,0.065,0.99125,56.91558,4,1
6,1181.34143,0.0661,1.008,57.18566,4,1
6.1,1186.79028,0.0672,1.02475,57.44942,4,1
6.2,1190.94092,0.06829,1.04137,57.65035,4,1
6.3,1194.20752,0.06936,1.05781,57.80848,4,1
6.4,1197.14246,0.07048,1.07481,57.95055,4,1
6.5,1198.74194,0.07157,1.09137,58.02797,4,1
6.6,1199.52893,0.07265,1.10787,58.06607,4,1
6.7,1199.74854,0.07375,1.12469,58.0767,4,1
6.8,1199.25818,0.07485,1.14144,58.05296,4,1
6.9,1197.2688,0.07593,1.15787,57.95666,4,1
6.944,672.89856,0.07643,1.16556,32.57327,4,1
0,1.04737,0,0,0.05099,5,1
0.1,13.24763,0.00089,0.0135,0.64492,5,1
0.2,49.49321,0.00216,0.03294,2.40941,5,1
0.3,76.94538,0.00327,0.04981,3.74583,5,1
0.4,104.28005,0.00437,0.06669,5.07653,5,1
0.5,131.30148,0.00547,0.08337,6.39198,5,1
0.6,157.63185,0.00656,0.1,7.67379,5,1
0.7,183.77779,0.00765,0.11662,8.94662,5,1
0.8,209.68127,0.00874,0.13331,10.20764,5,1
0.9,235.42027,0.00984,0.15006,11.46066,5,1
1,260.43298,0.01092,0.16656,12.67832,5,1
1.1,240.36932,0.01201,0.18312,11.70159,5,1
1.2,268.96841,0.01312,0.20006,13.09384,5,1
1.3,294.75531,0.01421,0.21669,14.34919,5,1
1.4,319.27368,0.01529,0.23319,15.54279,5,1
1.5,343.8736,0.01639,0.24987,16.74035,5,1
1.6,368.1178,0.01749,0.26675,17.9206,5,1
1.7,391.75845,0.01858,0.28331,19.07147,5,1
1.8,414.98099,0.01966,0.29987,20.20198,5,1
1.9,438.23138,0.02077,0.31669,21.33385,5,1
2,461.42731,0.02186,0.33331,22.46307,5,1
2.1,483.53848,0.02295,0.35,23.53948,5,1
2.2,505.80191,0.02404,0.36662,24.6233,5,1
2.3,527.94946,0.02514,0.38331,25.70148,5,1
2.4,549.53119,0.02623,0.40006,26.75211,5,1
2.5,570.75647,0.02732,0.41662,27.7854,5,1
2.6,591.10675,0.0284,0.43312,28.77608,5,1
2.7,612.50879,0.02951,0.45006,29.81797,5,1
2.8,633.06696,0.0306,0.46669,30.81878,5,1
2.9,652.94586,0.03169,0.48325,31.78652,5,1
3,672.86047,0.03279,0.5,32.75599,5,1
3.1,692.42615,0.03388,0.51669,33.70848,5,1
3.2,711.72699,0.03498,0.53337,34.64808,5,1
3.3,730.4834,0.03606,0.54994,35.56118,5,1
3.4,748.68805,0.03716,0.56662,36.44741,5,1
3.5,766.75146,0.03826,0.58344,37.32677,5,1
3.6,784.448,0.03934,0.6,38.18826,5,1
3.7,801.31348,0.04043,0.61656,39.0093,5,1
3.8,818.59583,0.04154,0.63344,39.85064,5,1
3.9,834.75641,0.04263,0.65006,40.63736,5,1
4,850.65356,0.04371,0.66656,41.41126,5,1
4.1,866.43042,0.0448,0.68325,42.17931,5,1
4.2,881.62665,0.0459,0.7,42.91909,5,1
4.3,896.71722,0.047,0.71675,43.65372,5,1
4.4,910.62646,0.04809,0.73331,44.33084,5,1
4.5,924.56561,0.04917,0.74987,45.00943,5,1
4.6,938.07599,0.05028,0.76681,45.66713,5,1
4.7,950.96826,0.05136,0.78331,46.29475,5,1
4.8,963.1004,0.05245,0.79987,46.88536,5,1
4.9,975.12976,0.05356,0.81675,47.47097,5,1
5,986.68353,0.05465,0.83337,48.03343,5,1
5.1,997.12701,0.05574,0.85006,48.54184,5,1
5.2,1007.39587,0.05682,0.86656,49.04174,5,1
5.3,1017.32184,0.05793,0.88337,49.52496,5,1
5.4,1026.4303,0.05902,0.90012,49.96837,5,1
5.5,1035.0498,0.06011,0.91662,50.38799,5,1
5.6,1043.07483,0.06119,0.93312,50.77866,5,1
5.7,1050.54602,0.0623,0.95012,51.14237,5,1
5.8,1057.69543,0.06339,0.96669,51.49041,5,1
5.9,1063.60168,0.06448,0.98331,51.77794,5,1
6,1069.53796,0.06557,0.99994,52.06693,5,1
6.1,1074.77637,0.06666,1.01662,52.32194,5,1
6.2,1079.43933,0.06776,1.03337,52.54894,5,1
6.3,1082.93262,0.06885,1.04994,52.719,5,1
6.4,1086.07617,0.06995,1.06669,52.87204,5,1
6.5,1088.88879,0.07105,1.0835,53.00896,5,1
6.6,1090.49597,0.07213,1.1,53.0872,5,1
6.7,1091.13831,0.07322,1.11656,53.11847,5,1
6.8,1091.48145,0.07432,1.13337,53.13517,5,1
6.9,1089.55945,0.07541,1.15,53.04161,5,1
6.942,630.84155,0.07588,1.15719,30.71044,5,1